Workbook

Sheet Stammdaten
A1: Klasse: | B1: 0x | C1: Fach: | D1: Demo | E1: Schuljahr: | F1: 9899
A2: Nachname | B2: Vorname | C2: Status | D2: Austrittsdatum | E2: Abgang_nach_HJ | F2: Aufnahme_ab_HJ | G2: Aufnahme_Vorh_HJ1 | H2: Aufnahme_Vorh_HJ2 | I2: Aufnahme_Vorh_HJ3
A3: Farnheim | B3: Goro | C3: Aktiv
A4: Silbersee | B4: Caro | C4: Aktiv
A5: Adlerquell | B5: Weya | C5: Aktiv
A6: Talwind | B6: Demi | C6: Ausgeschieden | E6: HJ1
A7: Nachtigall | B7: Alma | C7: Aktiv
A8: Kieselhain | B8: Tino | C8: Aktiv
A9: Talwind | B9: Goro | C9: Aktiv
A10: Kornfeld | B10: Nerio | C10: Aktiv
A11: Rosenquarz | B11: Vito | C11: Aktiv
A12: Seidenberg | B12: Miro | C12: Aktiv
A13: Kieselhain | B13: Pia | C13: Aktiv
A14: Blaustein | B14: Miro | C14: Aktiv
A15: Bergquell | B15: Ari | C15: Aktiv
A16: Talwind | B16: Jari | C16: Aktiv
A17: Farnheim | B17: Bino | C17: Aktiv
A18: Kieselhain | B18: Uma | C18: Aktiv
... A30: Lindenfels | B30: Hedi | C30: Aktiv

Sheet LN_GLN1
A1: LN_TYP | B1: GLN | C1: HJ | D1: HJ1 | E1: SL_ZUORDNUNG | G1: GLN_SLOT | I1: NACHTERMIN_VON | K1: NOTEN_RUNDEN | L1: 1
A2: Schüler | B2: Gesamt | C2: Note (0-15) | D2: Note (1-6) | E2: Ignoriert
A3: Anforderungsbereich
A4: Max. Punkte
A5: =Stammdaten!A3&", "&Stammdaten!B3 -> Farnheim, Goro
A6: =Stammdaten!A4&", "&Stammdaten!B4 -> Silbersee, Caro
A7: =Stammdaten!A5&", "&Stammdaten!B5 -> Adlerquell, Weya
A8: =Stammdaten!A6&", "&Stammdaten!B6 -> Talwind, Demi
A9: =Stammdaten!A7&", "&Stammdaten!B7 -> Nachtigall, Alma
A10: =Stammdaten!A8&", "&Stammdaten!B8 -> Kieselhain, Tino
A11: =Stammdaten!A9&", "&Stammdaten!B9 -> Talwind, Goro
A12: =Stammdaten!A10&", "&Stammdaten!B10 -> Kornfeld, Nerio
A13: =Stammdaten!A11&", "&Stammdaten!B11 -> Rosenquarz, Vito
A14: =Stammdaten!A12&", "&Stammdaten!B12 -> Seidenberg, Miro
A15: =Stammdaten!A13&", "&Stammdaten!B13 -> Kieselhain, Pia
A16: =Stammdaten!A14&", "&Stammdaten!B14 -> Blaustein, Miro
... A32: =Stammdaten!A30&", "&Stammdaten!B30 -> Lindenfels, Hedi

Sheet LN_KLN Krypto
A1: LN_TYP | B1: KLN | C1: HJ | E1: SL_ZUORDNUNG | F1: SL3 | G1: GLN_SLOT | I1: NACHTERMIN_VON | K1: NOTEN_RUNDEN | L1: 1
A2: Schüler | B2: 1 | C2: 2 | D2: 3 | E2: Gesamt | F2: Note (0-15) | G2: Note (1-6) | H2: Ignoriert
A3: Anforderungsbereich
A4: Max. Punkte | B4: 3.33 | C4: 1.67 | D4: 5 | E4: =SUM(B4:D4) -> 10
A5: =Stammdaten!A3&", "&Stammdaten!B3 -> Farnheim, Goro | B5: 0 | C5: 1.67 | D5: 5 | E5: =SUM(B5:D5) -> 6.67 | F5: =IF(E4=0,0,IF((E5/E4)>=0.95,15,IF((E5/E4)>=0.9,14,IF((E5/E4)>=0.85,13,IF((E5/E4)>=0.8,12,IF((E5/E4)>=0.75,11,IF((E5/E4)>=0.7,10,IF((E5/E4)>=0.65,9,IF((E5/E4)>=0.6,8,IF((E5/E4)>=0.55,7,IF((E5/E4)>=0.5,6,IF((E5/E4)>=0.45,5,IF((E5/E4)>=0.4,4,IF((E5/E4)>=0.33,3,IF((E5/E4)>=0.27,2,IF((E5/E4)>=0.2,1,0)))))))))))))))) -> 9 | G5: =IF(F5>=13,1,IF(F5>=10,2,IF(F5>=7,3,IF(F5>=4,4,IF(F5>=1,5,6))))) -> 3
A6: =Stammdaten!A4&", "&Stammdaten!B4 -> Silbersee, Caro | B6: 3.33 | C6: 1.67 | D6: 5 | E6: =SUM(B6:D6) -> 10 | F6: =IF(E4=0,0,IF((E6/E4)>=0.95,15,IF((E6/E4)>=0.9,14,IF((E6/E4)>=0.85,13,IF((E6/E4)>=0.8,12,IF((E6/E4)>=0.75,11,IF((E6/E4)>=0.7,10,IF((E6/E4)>=0.65,9,IF((E6/E4)>=0.6,8,IF((E6/E4)>=0.55,7,IF((E6/E4)>=0.5,6,IF((E6/E4)>=0.45,5,IF((E6/E4)>=0.4,4,IF((E6/E4)>=0.33,3,IF((E6/E4)>=0.27,2,IF((E6/E4)>=0.2,1,0)))))))))))))))) -> 15 | G6: =IF(F6>=13,1,IF(F6>=10,2,IF(F6>=7,3,IF(F6>=4,4,IF(F6>=1,5,6))))) -> 1
A7: =Stammdaten!A5&", "&Stammdaten!B5 -> Adlerquell, Weya | E7: =SUM(B7:D7) -> 0 | F7: =IF(E4=0,0,IF((E7/E4)>=0.95,15,IF((E7/E4)>=0.9,14,IF((E7/E4)>=0.85,13,IF((E7/E4)>=0.8,12,IF((E7/E4)>=0.75,11,IF((E7/E4)>=0.7,10,IF((E7/E4)>=0.65,9,IF((E7/E4)>=0.6,8,IF((E7/E4)>=0.55,7,IF((E7/E4)>=0.5,6,IF((E7/E4)>=0.45,5,IF((E7/E4)>=0.4,4,IF((E7/E4)>=0.33,3,IF((E7/E4)>=0.27,2,IF((E7/E4)>=0.2,1,0)))))))))))))))) -> 0 | G7: =IF(F7>=13,1,IF(F7>=10,2,IF(F7>=7,3,IF(F7>=4,4,IF(F7>=1,5,6))))) -> 6
A8: =Stammdaten!A6&", "&Stammdaten!B6 -> Talwind, Demi | B8: 0 | C8: 0 | D8: 5 | E8: =SUM(B8:D8) -> 5 | F8: =IF(E4=0,0,IF((E8/E4)>=0.95,15,IF((E8/E4)>=0.9,14,IF((E8/E4)>=0.85,13,IF((E8/E4)>=0.8,12,IF((E8/E4)>=0.75,11,IF((E8/E4)>=0.7,10,IF((E8/E4)>=0.65,9,IF((E8/E4)>=0.6,8,IF((E8/E4)>=0.55,7,IF((E8/E4)>=0.5,6,IF((E8/E4)>=0.45,5,IF((E8/E4)>=0.4,4,IF((E8/E4)>=0.33,3,IF((E8/E4)>=0.27,2,IF((E8/E4)>=0.2,1,0)))))))))))))))) -> 6 | G8: =IF(F8>=13,1,IF(F8>=10,2,IF(F8>=7,3,IF(F8>=4,4,IF(F8>=1,5,6))))) -> 4
A9: =Stammdaten!A7&", "&Stammdaten!B7 -> Nachtigall, Alma | B9: 0 | C9: 0.42 | D9: 5 | E9: =SUM(B9:D9) -> 5.42 | F9: =IF(E4=0,0,IF((E9/E4)>=0.95,15,IF((E9/E4)>=0.9,14,IF((E9/E4)>=0.85,13,IF((E9/E4)>=0.8,12,IF((E9/E4)>=0.75,11,IF((E9/E4)>=0.7,10,IF((E9/E4)>=0.65,9,IF((E9/E4)>=0.6,8,IF((E9/E4)>=0.55,7,IF((E9/E4)>=0.5,6,IF((E9/E4)>=0.45,5,IF((E9/E4)>=0.4,4,IF((E9/E4)>=0.33,3,IF((E9/E4)>=0.27,2,IF((E9/E4)>=0.2,1,0)))))))))))))))) -> 6 | G9: =IF(F9>=13,1,IF(F9>=10,2,IF(F9>=7,3,IF(F9>=4,4,IF(F9>=1,5,6))))) -> 4
A10: =Stammdaten!A8&", "&Stammdaten!B8 -> Kieselhain, Tino | B10: 3.33 | C10: 1.67 | D10: 4.5 | E10: =SUM(B10:D10) -> 9.5 | F10: =IF(E4=0,0,IF((E10/E4)>=0.95,15,IF((E10/E4)>=0.9,14,IF((E10/E4)>=0.85,13,IF((E10/E4)>=0.8,12,IF((E10/E4)>=0.75,11,IF((E10/E4)>=0.7,10,IF((E10/E4)>=0.65,9,IF((E10/E4)>=0.6,8,IF((E10/E4)>=0.55,7,IF((E10/E4)>=0.5,6,IF((E10/E4)>=0.45,5,IF((E10/E4)>=0.4,4,IF((E10/E4)>=0.33,3,IF((E10/E4)>=0.27,2,IF((E10/E4)>=0.2,1,0)))))))))))))))) -> 15 | G10: =IF(F10>=13,1,IF(F10>=10,2,IF(F10>=7,3,IF(F10>=4,4,IF(F10>=1,5,6))))) -> 1
A11: =Stammdaten!A9&", "&Stammdaten!B9 -> Talwind, Goro | B11: 0 | C11: 0 | D11: 5 | E11: =SUM(B11:D11) -> 5 | F11: =IF(E4=0,0,IF((E11/E4)>=0.95,15,IF((E11/E4)>=0.9,14,IF((E11/E4)>=0.85,13,IF((E11/E4)>=0.8,12,IF((E11/E4)>=0.75,11,IF((E11/E4)>=0.7,10,IF((E11/E4)>=0.65,9,IF((E11/E4)>=0.6,8,IF((E11/E4)>=0.55,7,IF((E11/E4)>=0.5,6,IF((E11/E4)>=0.45,5,IF((E11/E4)>=0.4,4,IF((E11/E4)>=0.33,3,IF((E11/E4)>=0.27,2,IF((E11/E4)>=0.2,1,0)))))))))))))))) -> 6 | G11: =IF(F11>=13,1,IF(F11>=10,2,IF(F11>=7,3,IF(F11>=4,4,IF(F11>=1,5,6))))) -> 4
A12: =Stammdaten!A10&", "&Stammdaten!B10 -> Kornfeld, Nerio | B12: 3.33 | C12: 1.5 | D12: 5 | E12: =SUM(B12:D12) -> 9.83 | F12: =IF(E4=0,0,IF((E12/E4)>=0.95,15,IF((E12/E4)>=0.9,14,IF((E12/E4)>=0.85,13,IF((E12/E4)>=0.8,12,IF((E12/E4)>=0.75,11,IF((E12/E4)>=0.7,10,IF((E12/E4)>=0.65,9,IF((E12/E4)>=0.6,8,IF((E12/E4)>=0.55,7,IF((E12/E4)>=0.5,6,IF((E12/E4)>=0.45,5,IF((E12/E4)>=0.4,4,IF((E12/E4)>=0.33,3,IF((E12/E4)>=0.27,2,IF((E12/E4)>=0.2,1,0)))))))))))))))) -> 15 | G12: =IF(F12>=13,1,IF(F12>=10,2,IF(F12>=7,3,IF(F12>=4,4,IF(F12>=1,5,6))))) -> 1
A13: =Stammdaten!A11&", "&Stammdaten!B11 -> Rosenquarz, Vito | B13: 3.33 | C13: 1.25 | D13: 0 | E13: =SUM(B13:D13) -> 4.58 | F13: =IF(E4=0,0,IF((E13/E4)>=0.95,15,IF((E13/E4)>=0.9,14,IF((E13/E4)>=0.85,13,IF((E13/E4)>=0.8,12,IF((E13/E4)>=0.75,11,IF((E13/E4)>=0.7,10,IF((E13/E4)>=0.65,9,IF((E13/E4)>=0.6,8,IF((E13/E4)>=0.55,7,IF((E13/E4)>=0.5,6,IF((E13/E4)>=0.45,5,IF((E13/E4)>=0.4,4,IF((E13/E4)>=0.33,3,IF((E13/E4)>=0.27,2,IF((E13/E4)>=0.2,1,0)))))))))))))))) -> 5 | G13: =IF(F13>=13,1,IF(F13>=10,2,IF(F13>=7,3,IF(F13>=4,4,IF(F13>=1,5,6))))) -> 4
A14: =Stammdaten!A12&", "&Stammdaten!B12 -> Seidenberg, Miro | B14: 0 | C14: 0.42 | D14: 4 | E14: =SUM(B14:D14) -> 4.42 | F14: =IF(E4=0,0,IF((E14/E4)>=0.95,15,IF((E14/E4)>=0.9,14,IF((E14/E4)>=0.85,13,IF((E14/E4)>=0.8,12,IF((E14/E4)>=0.75,11,IF((E14/E4)>=0.7,10,IF((E14/E4)>=0.65,9,IF((E14/E4)>=0.6,8,IF((E14/E4)>=0.55,7,IF((E14/E4)>=0.5,6,IF((E14/E4)>=0.45,5,IF((E14/E4)>=0.4,4,IF((E14/E4)>=0.33,3,IF((E14/E4)>=0.27,2,IF((E14/E4)>=0.2,1,0)))))))))))))))) -> 4 | G14: =IF(F14>=13,1,IF(F14>=10,2,IF(F14>=7,3,IF(F14>=4,4,IF(F14>=1,5,6))))) -> 4
A15: =Stammdaten!A13&", "&Stammdaten!B13 -> Kieselhain, Pia | E15: =SUM(B15:D15) -> 0 | F15: =IF(E4=0,0,IF((E15/E4)>=0.95,15,IF((E15/E4)>=0.9,14,IF((E15/E4)>=0.85,13,IF((E15/E4)>=0.8,12,IF((E15/E4)>=0.75,11,IF((E15/E4)>=0.7,10,IF((E15/E4)>=0.65,9,IF((E15/E4)>=0.6,8,IF((E15/E4)>=0.55,7,IF((E15/E4)>=0.5,6,IF((E15/E4)>=0.45,5,IF((E15/E4)>=0.4,4,IF((E15/E4)>=0.33,3,IF((E15/E4)>=0.27,2,IF((E15/E4)>=0.2,1,0)))))))))))))))) -> 0 | G15: =IF(F15>=13,1,IF(F15>=10,2,IF(F15>=7,3,IF(F15>=4,4,IF(F15>=1,5,6))))) -> 6
A16: =Stammdaten!A14&", "&Stammdaten!B14 -> Blaustein, Miro | C16: 1.67 | D16: 5 | E16: =SUM(B16:D16) -> 6.67 | F16: =IF(E4=0,0,IF((E16/E4)>=0.95,15,IF((E16/E4)>=0.9,14,IF((E16/E4)>=0.85,13,IF((E16/E4)>=0.8,12,IF((E16/E4)>=0.75,11,IF((E16/E4)>=0.7,10,IF((E16/E4)>=0.65,9,IF((E16/E4)>=0.6,8,IF((E16/E4)>=0.55,7,IF((E16/E4)>=0.5,6,IF((E16/E4)>=0.45,5,IF((E16/E4)>=0.4,4,IF((E16/E4)>=0.33,3,IF((E16/E4)>=0.27,2,IF((E16/E4)>=0.2,1,0)))))))))))))))) -> 9 | G16: =IF(F16>=13,1,IF(F16>=10,2,IF(F16>=7,3,IF(F16>=4,4,IF(F16>=1,5,6))))) -> 3
A17: =Stammdaten!A15&", "&Stammdaten!B15 -> Bergquell, Ari | B17: 0 | C17: 0 | D17: 4.5 | E17: =SUM(B17:D17) -> 4.5 | F17: =IF(E4=0,0,IF((E17/E4)>=0.95,15,IF((E17/E4)>=0.9,14,IF((E17/E4)>=0.85,13,IF((E17/E4)>=0.8,12,IF((E17/E4)>=0.75,11,IF((E17/E4)>=0.7,10,IF((E17/E4)>=0.65,9,IF((E17/E4)>=0.6,8,IF((E17/E4)>=0.55,7,IF((E17/E4)>=0.5,6,IF((E17/E4)>=0.45,5,IF((E17/E4)>=0.4,4,IF((E17/E4)>=0.33,3,IF((E17/E4)>=0.27,2,IF((E17/E4)>=0.2,1,0)))))))))))))))) -> 5 | G17: =IF(F17>=13,1,IF(F17>=10,2,IF(F17>=7,3,IF(F17>=4,4,IF(F17>=1,5,6))))) -> 4
A18: =Stammdaten!A16&", "&Stammdaten!B16 -> Talwind, Jari | B18: 3.33 | C18: 0 | D18: 2.5 | E18: =SUM(B18:D18) -> 5.83 | F18: =IF(E4=0,0,IF((E18/E4)>=0.95,15,IF((E18/E4)>=0.9,14,IF((E18/E4)>=0.85,13,IF((E18/E4)>=0.8,12,IF((E18/E4)>=0.75,11,IF((E18/E4)>=0.7,10,IF((E18/E4)>=0.65,9,IF((E18/E4)>=0.6,8,IF((E18/E4)>=0.55,7,IF((E18/E4)>=0.5,6,IF((E18/E4)>=0.45,5,IF((E18/E4)>=0.4,4,IF((E18/E4)>=0.33,3,IF((E18/E4)>=0.27,2,IF((E18/E4)>=0.2,1,0)))))))))))))))) -> 7 | G18: =IF(F18>=13,1,IF(F18>=10,2,IF(F18>=7,3,IF(F18>=4,4,IF(F18>=1,5,6))))) -> 3
A19: =Stammdaten!A17&", "&Stammdaten!B17 -> Farnheim, Bino | B19: 3.33 | C19: 1.67 | D19: 5 | E19: =SUM(B19:D19) -> 10 | F19: =IF(E4=0,0,IF((E19/E4)>=0.95,15,IF((E19/E4)>=0.9,14,IF((E19/E4)>=0.85,13,IF((E19/E4)>=0.8,12,IF((E19/E4)>=0.75,11,IF((E19/E4)>=0.7,10,IF((E19/E4)>=0.65,9,IF((E19/E4)>=0.6,8,IF((E19/E4)>=0.55,7,IF((E19/E4)>=0.5,6,IF((E19/E4)>=0.45,5,IF((E19/E4)>=0.4,4,IF((E19/E4)>=0.33,3,IF((E19/E4)>=0.27,2,IF((E19/E4)>=0.2,1,0)))))))))))))))) -> 15 | G19: =IF(F19>=13,1,IF(F19>=10,2,IF(F19>=7,3,IF(F19>=4,4,IF(F19>=1,5,6))))) -> 1
A20: =Stammdaten!A19&", "&Stammdaten!B19 -> Tannenhof, Gina | B20: 0 | C20: 1.67 | D20: 5 | E20: =SUM(B20:D20) -> 6.67 | F20: =IF(E4=0,0,IF((E20/E4)>=0.95,15,IF((E20/E4)>=0.9,14,IF((E20/E4)>=0.85,13,IF((E20/E4)>=0.8,12,IF((E20/E4)>=0.75,11,IF((E20/E4)>=0.7,10,IF((E20/E4)>=0.65,9,IF((E20/E4)>=0.6,8,IF((E20/E4)>=0.55,7,IF((E20/E4)>=0.5,6,IF((E20/E4)>=0.45,5,IF((E20/E4)>=0.4,4,IF((E20/E4)>=0.33,3,IF((E20/E4)>=0.27,2,IF((E20/E4)>=0.2,1,0)))))))))))))))) -> 9 | G20: =IF(F20>=13,1,IF(F20>=10,2,IF(F20>=7,3,IF(F20>=4,4,IF(F20>=1,5,6))))) -> 3
A21: =Stammdaten!A20&", "&Stammdaten!B20 -> Lindenfels, Miro | B21: 0 | C21: 0.42 | D21: 5 | E21: =SUM(B21:D21) -> 5.42 | F21: =IF(E4=0,0,IF((E21/E4)>=0.95,15,IF((E21/E4)>=0.9,14,IF((E21/E4)>=0.85,13,IF((E21/E4)>=0.8,12,IF((E21/E4)>=0.75,11,IF((E21/E4)>=0.7,10,IF((E21/E4)>=0.65,9,IF((E21/E4)>=0.6,8,IF((E21/E4)>=0.55,7,IF((E21/E4)>=0.5,6,IF((E21/E4)>=0.45,5,IF((E21/E4)>=0.4,4,IF((E21/E4)>=0.33,3,IF((E21/E4)>=0.27,2,IF((E21/E4)>=0.2,1,0)))))))))))))))) -> 6 | G21: =IF(F21>=13,1,IF(F21>=10,2,IF(F21>=7,3,IF(F21>=4,4,IF(F21>=1,5,6))))) -> 4
A22: =Stammdaten!A21&", "&Stammdaten!B21 -> Adlerquell, Bino | B22: 3.33 | C22: 0 | D22: 0.5 | E22: =SUM(B22:D22) -> 3.83 | F22: =IF(E4=0,0,IF((E22/E4)>=0.95,15,IF((E22/E4)>=0.9,14,IF((E22/E4)>=0.85,13,IF((E22/E4)>=0.8,12,IF((E22/E4)>=0.75,11,IF((E22/E4)>=0.7,10,IF((E22/E4)>=0.65,9,IF((E22/E4)>=0.6,8,IF((E22/E4)>=0.55,7,IF((E22/E4)>=0.5,6,IF((E22/E4)>=0.45,5,IF((E22/E4)>=0.4,4,IF((E22/E4)>=0.33,3,IF((E22/E4)>=0.27,2,IF((E22/E4)>=0.2,1,0)))))))))))))))) -> 3 | G22: =IF(F22>=13,1,IF(F22>=10,2,IF(F22>=7,3,IF(F22>=4,4,IF(F22>=1,5,6))))) -> 5
A23: =Stammdaten!A22&", "&Stammdaten!B22 -> Bergquell, Caro | B23: 0 | C23: 0.42 | D23: 4 | E23: =SUM(B23:D23) -> 4.42 | F23: =IF(E4=0,0,IF((E23/E4)>=0.95,15,IF((E23/E4)>=0.9,14,IF((E23/E4)>=0.85,13,IF((E23/E4)>=0.8,12,IF((E23/E4)>=0.75,11,IF((E23/E4)>=0.7,10,IF((E23/E4)>=0.65,9,IF((E23/E4)>=0.6,8,IF((E23/E4)>=0.55,7,IF((E23/E4)>=0.5,6,IF((E23/E4)>=0.45,5,IF((E23/E4)>=0.4,4,IF((E23/E4)>=0.33,3,IF((E23/E4)>=0.27,2,IF((E23/E4)>=0.2,1,0)))))))))))))))) -> 4 | G23: =IF(F23>=13,1,IF(F23>=10,2,IF(F23>=7,3,IF(F23>=4,4,IF(F23>=1,5,6))))) -> 4
A24: =Stammdaten!A23&", "&Stammdaten!B23 -> Waldhauch, Gina | B24: 3.33 | C24: 1.67 | D24: 5 | E24: =SUM(B24:D24) -> 10 | F24: =IF(E4=0,0,IF((E24/E4)>=0.95,15,IF((E24/E4)>=0.9,14,IF((E24/E4)>=0.85,13,IF((E24/E4)>=0.8,12,IF((E24/E4)>=0.75,11,IF((E24/E4)>=0.7,10,IF((E24/E4)>=0.65,9,IF((E24/E4)>=0.6,8,IF((E24/E4)>=0.55,7,IF((E24/E4)>=0.5,6,IF((E24/E4)>=0.45,5,IF((E24/E4)>=0.4,4,IF((E24/E4)>=0.33,3,IF((E24/E4)>=0.27,2,IF((E24/E4)>=0.2,1,0)))))))))))))))) -> 15 | G24: =IF(F24>=13,1,IF(F24>=10,2,IF(F24>=7,3,IF(F24>=4,4,IF(F24>=1,5,6))))) -> 1
A25: =Stammdaten!A24&", "&Stammdaten!B24 -> Silbersee, Miro | B25: 0 | C25: 0.42 | D25: 4 | E25: =SUM(B25:D25) -> 4.42 | F25: =IF(E4=0,0,IF((E25/E4)>=0.95,15,IF((E25/E4)>=0.9,14,IF((E25/E4)>=0.85,13,IF((E25/E4)>=0.8,12,IF((E25/E4)>=0.75,11,IF((E25/E4)>=0.7,10,IF((E25/E4)>=0.65,9,IF((E25/E4)>=0.6,8,IF((E25/E4)>=0.55,7,IF((E25/E4)>=0.5,6,IF((E25/E4)>=0.45,5,IF((E25/E4)>=0.4,4,IF((E25/E4)>=0.33,3,IF((E25/E4)>=0.27,2,IF((E25/E4)>=0.2,1,0)))))))))))))))) -> 4 | G25: =IF(F25>=13,1,IF(F25>=10,2,IF(F25>=7,3,IF(F25>=4,4,IF(F25>=1,5,6))))) -> 4
A26: =Stammdaten!A25&", "&Stammdaten!B25 -> Winterborn, Raya | B26: 0 | C26: 0.83 | D26: 1.25 | E26: =SUM(B26:D26) -> 2.08 | F26: =IF(E4=0,0,IF((E26/E4)>=0.95,15,IF((E26/E4)>=0.9,14,IF((E26/E4)>=0.85,13,IF((E26/E4)>=0.8,12,IF((E26/E4)>=0.75,11,IF((E26/E4)>=0.7,10,IF((E26/E4)>=0.65,9,IF((E26/E4)>=0.6,8,IF((E26/E4)>=0.55,7,IF((E26/E4)>=0.5,6,IF((E26/E4)>=0.45,5,IF((E26/E4)>=0.4,4,IF((E26/E4)>=0.33,3,IF((E26/E4)>=0.27,2,IF((E26/E4)>=0.2,1,0)))))))))))))))) -> 1 | G26: =IF(F26>=13,1,IF(F26>=10,2,IF(F26>=7,3,IF(F26>=4,4,IF(F26>=1,5,6))))) -> 5
A27: =Stammdaten!A26&", "&Stammdaten!B26 -> Rosenquarz, Ivo | B27: 3.33 | C27: 1.67 | D27: 5 | E27: =SUM(B27:D27) -> 10 | F27: =IF(E4=0,0,IF((E27/E4)>=0.95,15,IF((E27/E4)>=0.9,14,IF((E27/E4)>=0.85,13,IF((E27/E4)>=0.8,12,IF((E27/E4)>=0.75,11,IF((E27/E4)>=0.7,10,IF((E27/E4)>=0.65,9,IF((E27/E4)>=0.6,8,IF((E27/E4)>=0.55,7,IF((E27/E4)>=0.5,6,IF((E27/E4)>=0.45,5,IF((E27/E4)>=0.4,4,IF((E27/E4)>=0.33,3,IF((E27/E4)>=0.27,2,IF((E27/E4)>=0.2,1,0)))))))))))))))) -> 15 | G27: =IF(F27>=13,1,IF(F27>=10,2,IF(F27>=7,3,IF(F27>=4,4,IF(F27>=1,5,6))))) -> 1
A28: =Stammdaten!A27&", "&Stammdaten!B27 -> Mondenfels, Alma | B28: 0 | C28: 0 | D28: 0 | E28: =SUM(B28:D28) -> 0 | F28: =IF(E4=0,0,IF((E28/E4)>=0.95,15,IF((E28/E4)>=0.9,14,IF((E28/E4)>=0.85,13,IF((E28/E4)>=0.8,12,IF((E28/E4)>=0.75,11,IF((E28/E4)>=0.7,10,IF((E28/E4)>=0.65,9,IF((E28/E4)>=0.6,8,IF((E28/E4)>=0.55,7,IF((E28/E4)>=0.5,6,IF((E28/E4)>=0.45,5,IF((E28/E4)>=0.4,4,IF((E28/E4)>=0.33,3,IF((E28/E4)>=0.27,2,IF((E28/E4)>=0.2,1,0)))))))))))))))) -> 0 | G28: =IF(F28>=13,1,IF(F28>=10,2,IF(F28>=7,3,IF(F28>=4,4,IF(F28>=1,5,6))))) -> 6
A29: =Stammdaten!A28&", "&Stammdaten!B28 -> Wolkenberg, Navi | B29: 3.33 | C29: 0 | D29: 5 | E29: =SUM(B29:D29) -> 8.33 | F29: =IF(E4=0,0,IF((E29/E4)>=0.95,15,IF((E29/E4)>=0.9,14,IF((E29/E4)>=0.85,13,IF((E29/E4)>=0.8,12,IF((E29/E4)>=0.75,11,IF((E29/E4)>=0.7,10,IF((E29/E4)>=0.65,9,IF((E29/E4)>=0.6,8,IF((E29/E4)>=0.55,7,IF((E29/E4)>=0.5,6,IF((E29/E4)>=0.45,5,IF((E29/E4)>=0.4,4,IF((E29/E4)>=0.33,3,IF((E29/E4)>=0.27,2,IF((E29/E4)>=0.2,1,0)))))))))))))))) -> 12 | G29: =IF(F29>=13,1,IF(F29>=10,2,IF(F29>=7,3,IF(F29>=4,4,IF(F29>=1,5,6))))) -> 2
A30: =Stammdaten!A29&", "&Stammdaten!B29 -> Nordlicht, Navi | B30: 3.33 | C30: 0 | D30: 2.5 | E30: =SUM(B30:D30) -> 5.83 | F30: =IF(E4=0,0,IF((E30/E4)>=0.95,15,IF((E30/E4)>=0.9,14,IF((E30/E4)>=0.85,13,IF((E30/E4)>=0.8,12,IF((E30/E4)>=0.75,11,IF((E30/E4)>=0.7,10,IF((E30/E4)>=0.65,9,IF((E30/E4)>=0.6,8,IF((E30/E4)>=0.55,7,IF((E30/E4)>=0.5,6,IF((E30/E4)>=0.45,5,IF((E30/E4)>=0.4,4,IF((E30/E4)>=0.33,3,IF((E30/E4)>=0.27,2,IF((E30/E4)>=0.2,1,0)))))))))))))))) -> 7 | G30: =IF(F30>=13,1,IF(F30>=10,2,IF(F30>=7,3,IF(F30>=4,4,IF(F30>=1,5,6))))) -> 3
A31: =Stammdaten!A30&", "&Stammdaten!B30 -> Lindenfels, Hedi | B31: 3.33 | C31: 0.42 | D31: 5 | E31: =SUM(B31:D31) -> 8.75 | F31: =IF(E4=0,0,IF((E31/E4)>=0.95,15,IF((E31/E4)>=0.9,14,IF((E31/E4)>=0.85,13,IF((E31/E4)>=0.8,12,IF((E31/E4)>=0.75,11,IF((E31/E4)>=0.7,10,IF((E31/E4)>=0.65,9,IF((E31/E4)>=0.6,8,IF((E31/E4)>=0.55,7,IF((E31/E4)>=0.5,6,IF((E31/E4)>=0.45,5,IF((E31/E4)>=0.4,4,IF((E31/E4)>=0.33,3,IF((E31/E4)>=0.27,2,IF((E31/E4)>=0.2,1,0)))))))))))))))) -> 13 | G31: =IF(F31>=13,1,IF(F31>=10,2,IF(F31>=7,3,IF(F31>=4,4,IF(F31>=1,5,6))))) -> 1

Sheet LN_KLN KI
A1: LN_TYP | B1: KLN | C1: HJ | E1: SL_ZUORDNUNG | F1: SL4 | G1: GLN_SLOT | I1: NACHTERMIN_VON | K1: NOTEN_RUNDEN | L1: 1
A2: Schüler | B2: 1 | C2: 2 | D2: 3 | E2: Gesamt | F2: Note (0-15) | G2: Note (1-6) | H2: Ignoriert
A3: Anforderungsbereich
A4: Max. Punkte | B4: 2 | C4: 3 | D4: 2 | E4: =SUM(B4:D4) -> 7
A5: =Stammdaten!A3&", "&Stammdaten!B3 -> Farnheim, Goro | B5: 1.89 | C5: 3 | D5: 0.2 | E5: =SUM(B5:D5) -> 5.09 | F5: =IF(E4=0,0,IF((E5/E4)>=0.95,15,IF((E5/E4)>=0.9,14,IF((E5/E4)>=0.85,13,IF((E5/E4)>=0.8,12,IF((E5/E4)>=0.75,11,IF((E5/E4)>=0.7,10,IF((E5/E4)>=0.65,9,IF((E5/E4)>=0.6,8,IF((E5/E4)>=0.55,7,IF((E5/E4)>=0.5,6,IF((E5/E4)>=0.45,5,IF((E5/E4)>=0.4,4,IF((E5/E4)>=0.33,3,IF((E5/E4)>=0.27,2,IF((E5/E4)>=0.2,1,0)))))))))))))))) -> 10 | G5: =IF(F5>=13,1,IF(F5>=10,2,IF(F5>=7,3,IF(F5>=4,4,IF(F5>=1,5,6))))) -> 2
A6: =Stammdaten!A4&", "&Stammdaten!B4 -> Silbersee, Caro | B6: 2 | C6: 0 | D6: 0.2 | E6: =SUM(B6:D6) -> 2.2 | F6: =IF(E4=0,0,IF((E6/E4)>=0.95,15,IF((E6/E4)>=0.9,14,IF((E6/E4)>=0.85,13,IF((E6/E4)>=0.8,12,IF((E6/E4)>=0.75,11,IF((E6/E4)>=0.7,10,IF((E6/E4)>=0.65,9,IF((E6/E4)>=0.6,8,IF((E6/E4)>=0.55,7,IF((E6/E4)>=0.5,6,IF((E6/E4)>=0.45,5,IF((E6/E4)>=0.4,4,IF((E6/E4)>=0.33,3,IF((E6/E4)>=0.27,2,IF((E6/E4)>=0.2,1,0)))))))))))))))) -> 2 | G6: =IF(F6>=13,1,IF(F6>=10,2,IF(F6>=7,3,IF(F6>=4,4,IF(F6>=1,5,6))))) -> 5
A7: =Stammdaten!A5&", "&Stammdaten!B5 -> Adlerquell, Weya | B7: 1.89 | C7: 3 | E7: =SUM(B7:D7) -> 4.89 | F7: =IF(E4=0,0,IF((E7/E4)>=0.95,15,IF((E7/E4)>=0.9,14,IF((E7/E4)>=0.85,13,IF((E7/E4)>=0.8,12,IF((E7/E4)>=0.75,11,IF((E7/E4)>=0.7,10,IF((E7/E4)>=0.65,9,IF((E7/E4)>=0.6,8,IF((E7/E4)>=0.55,7,IF((E7/E4)>=0.5,6,IF((E7/E4)>=0.45,5,IF((E7/E4)>=0.4,4,IF((E7/E4)>=0.33,3,IF((E7/E4)>=0.27,2,IF((E7/E4)>=0.2,1,0)))))))))))))))) -> 9 | G7: =IF(F7>=13,1,IF(F7>=10,2,IF(F7>=7,3,IF(F7>=4,4,IF(F7>=1,5,6))))) -> 3
A8: =Stammdaten!A6&", "&Stammdaten!B6 -> Talwind, Demi | E8: =SUM(B8:D8) -> 0 | F8: =IF(E4=0,0,IF((E8/E4)>=0.95,15,IF((E8/E4)>=0.9,14,IF((E8/E4)>=0.85,13,IF((E8/E4)>=0.8,12,IF((E8/E4)>=0.75,11,IF((E8/E4)>=0.7,10,IF((E8/E4)>=0.65,9,IF((E8/E4)>=0.6,8,IF((E8/E4)>=0.55,7,IF((E8/E4)>=0.5,6,IF((E8/E4)>=0.45,5,IF((E8/E4)>=0.4,4,IF((E8/E4)>=0.33,3,IF((E8/E4)>=0.27,2,IF((E8/E4)>=0.2,1,0)))))))))))))))) -> 0 | G8: =IF(F8>=13,1,IF(F8>=10,2,IF(F8>=7,3,IF(F8>=4,4,IF(F8>=1,5,6))))) -> 6
A9: =Stammdaten!A7&", "&Stammdaten!B7 -> Nachtigall, Alma | B9: 1.72 | C9: 2 | D9: 0 | E9: =SUM(B9:D9) -> 3.72 | F9: =IF(E4=0,0,IF((E9/E4)>=0.95,15,IF((E9/E4)>=0.9,14,IF((E9/E4)>=0.85,13,IF((E9/E4)>=0.8,12,IF((E9/E4)>=0.75,11,IF((E9/E4)>=0.7,10,IF((E9/E4)>=0.65,9,IF((E9/E4)>=0.6,8,IF((E9/E4)>=0.55,7,IF((E9/E4)>=0.5,6,IF((E9/E4)>=0.45,5,IF((E9/E4)>=0.4,4,IF((E9/E4)>=0.33,3,IF((E9/E4)>=0.27,2,IF((E9/E4)>=0.2,1,0)))))))))))))))) -> 6 | G9: =IF(F9>=13,1,IF(F9>=10,2,IF(F9>=7,3,IF(F9>=4,4,IF(F9>=1,5,6))))) -> 4
A10: =Stammdaten!A8&", "&Stammdaten!B8 -> Kieselhain, Tino | B10: 1.89 | C10: 2 | D10: 0.4 | E10: =SUM(B10:D10) -> 4.29 | F10: =IF(E4=0,0,IF((E10/E4)>=0.95,15,IF((E10/E4)>=0.9,14,IF((E10/E4)>=0.85,13,IF((E10/E4)>=0.8,12,IF((E10/E4)>=0.75,11,IF((E10/E4)>=0.7,10,IF((E10/E4)>=0.65,9,IF((E10/E4)>=0.6,8,IF((E10/E4)>=0.55,7,IF((E10/E4)>=0.5,6,IF((E10/E4)>=0.45,5,IF((E10/E4)>=0.4,4,IF((E10/E4)>=0.33,3,IF((E10/E4)>=0.27,2,IF((E10/E4)>=0.2,1,0)))))))))))))))) -> 8 | G10: =IF(F10>=13,1,IF(F10>=10,2,IF(F10>=7,3,IF(F10>=4,4,IF(F10>=1,5,6))))) -> 3
A11: =Stammdaten!A9&", "&Stammdaten!B9 -> Talwind, Goro | B11: 2 | C11: 2 | D11: 2 | E11: =SUM(B11:D11) -> 6 | F11: =IF(E4=0,0,IF((E11/E4)>=0.95,15,IF((E11/E4)>=0.9,14,IF((E11/E4)>=0.85,13,IF((E11/E4)>=0.8,12,IF((E11/E4)>=0.75,11,IF((E11/E4)>=0.7,10,IF((E11/E4)>=0.65,9,IF((E11/E4)>=0.6,8,IF((E11/E4)>=0.55,7,IF((E11/E4)>=0.5,6,IF((E11/E4)>=0.45,5,IF((E11/E4)>=0.4,4,IF((E11/E4)>=0.33,3,IF((E11/E4)>=0.27,2,IF((E11/E4)>=0.2,1,0)))))))))))))))) -> 13 | G11: =IF(F11>=13,1,IF(F11>=10,2,IF(F11>=7,3,IF(F11>=4,4,IF(F11>=1,5,6))))) -> 1
A12: =Stammdaten!A10&", "&Stammdaten!B10 -> Kornfeld, Nerio | B12: 2 | C12: 2 | D12: 0 | E12: =SUM(B12:D12) -> 4 | F12: =IF(E4=0,0,IF((E12/E4)>=0.95,15,IF((E12/E4)>=0.9,14,IF((E12/E4)>=0.85,13,IF((E12/E4)>=0.8,12,IF((E12/E4)>=0.75,11,IF((E12/E4)>=0.7,10,IF((E12/E4)>=0.65,9,IF((E12/E4)>=0.6,8,IF((E12/E4)>=0.55,7,IF((E12/E4)>=0.5,6,IF((E12/E4)>=0.45,5,IF((E12/E4)>=0.4,4,IF((E12/E4)>=0.33,3,IF((E12/E4)>=0.27,2,IF((E12/E4)>=0.2,1,0)))))))))))))))) -> 7 | G12: =IF(F12>=13,1,IF(F12>=10,2,IF(F12>=7,3,IF(F12>=4,4,IF(F12>=1,5,6))))) -> 3
A13: =Stammdaten!A11&", "&Stammdaten!B11 -> Rosenquarz, Vito | B13: 1.89 | C13: 2 | D13: 1.2 | E13: =SUM(B13:D13) -> 5.09 | F13: =IF(E4=0,0,IF((E13/E4)>=0.95,15,IF((E13/E4)>=0.9,14,IF((E13/E4)>=0.85,13,IF((E13/E4)>=0.8,12,IF((E13/E4)>=0.75,11,IF((E13/E4)>=0.7,10,IF((E13/E4)>=0.65,9,IF((E13/E4)>=0.6,8,IF((E13/E4)>=0.55,7,IF((E13/E4)>=0.5,6,IF((E13/E4)>=0.45,5,IF((E13/E4)>=0.4,4,IF((E13/E4)>=0.33,3,IF((E13/E4)>=0.27,2,IF((E13/E4)>=0.2,1,0)))))))))))))))) -> 10 | G13: =IF(F13>=13,1,IF(F13>=10,2,IF(F13>=7,3,IF(F13>=4,4,IF(F13>=1,5,6))))) -> 2
A14: =Stammdaten!A12&", "&Stammdaten!B12 -> Seidenberg, Miro | B14: 1.61 | C14: 2 | D14: 2 | E14: =SUM(B14:D14) -> 5.61 | F14: =IF(E4=0,0,IF((E14/E4)>=0.95,15,IF((E14/E4)>=0.9,14,IF((E14/E4)>=0.85,13,IF((E14/E4)>=0.8,12,IF((E14/E4)>=0.75,11,IF((E14/E4)>=0.7,10,IF((E14/E4)>=0.65,9,IF((E14/E4)>=0.6,8,IF((E14/E4)>=0.55,7,IF((E14/E4)>=0.5,6,IF((E14/E4)>=0.45,5,IF((E14/E4)>=0.4,4,IF((E14/E4)>=0.33,3,IF((E14/E4)>=0.27,2,IF((E14/E4)>=0.2,1,0)))))))))))))))) -> 12 | G14: =IF(F14>=13,1,IF(F14>=10,2,IF(F14>=7,3,IF(F14>=4,4,IF(F14>=1,5,6))))) -> 2
A15: =Stammdaten!A13&", "&Stammdaten!B13 -> Kieselhain, Pia | B15: 1.83 | C15: 2 | D15: 0 | E15: =SUM(B15:D15) -> 3.83 | F15: =IF(E4=0,0,IF((E15/E4)>=0.95,15,IF((E15/E4)>=0.9,14,IF((E15/E4)>=0.85,13,IF((E15/E4)>=0.8,12,IF((E15/E4)>=0.75,11,IF((E15/E4)>=0.7,10,IF((E15/E4)>=0.65,9,IF((E15/E4)>=0.6,8,IF((E15/E4)>=0.55,7,IF((E15/E4)>=0.5,6,IF((E15/E4)>=0.45,5,IF((E15/E4)>=0.4,4,IF((E15/E4)>=0.33,3,IF((E15/E4)>=0.27,2,IF((E15/E4)>=0.2,1,0)))))))))))))))) -> 6 | G15: =IF(F15>=13,1,IF(F15>=10,2,IF(F15>=7,3,IF(F15>=4,4,IF(F15>=1,5,6))))) -> 4
A16: =Stammdaten!A14&", "&Stammdaten!B14 -> Blaustein, Miro | B16: 1.61 | C16: 0 | D16: 0.2 | E16: =SUM(B16:D16) -> 1.81 | F16: =IF(E4=0,0,IF((E16/E4)>=0.95,15,IF((E16/E4)>=0.9,14,IF((E16/E4)>=0.85,13,IF((E16/E4)>=0.8,12,IF((E16/E4)>=0.75,11,IF((E16/E4)>=0.7,10,IF((E16/E4)>=0.65,9,IF((E16/E4)>=0.6,8,IF((E16/E4)>=0.55,7,IF((E16/E4)>=0.5,6,IF((E16/E4)>=0.45,5,IF((E16/E4)>=0.4,4,IF((E16/E4)>=0.33,3,IF((E16/E4)>=0.27,2,IF((E16/E4)>=0.2,1,0)))))))))))))))) -> 1 | G16: =IF(F16>=13,1,IF(F16>=10,2,IF(F16>=7,3,IF(F16>=4,4,IF(F16>=1,5,6))))) -> 5
A17: =Stammdaten!A15&", "&Stammdaten!B15 -> Bergquell, Ari | B17: 2 | C17: 3 | D17: 0.6 | E17: =SUM(B17:D17) -> 5.6 | F17: =IF(E4=0,0,IF((E17/E4)>=0.95,15,IF((E17/E4)>=0.9,14,IF((E17/E4)>=0.85,13,IF((E17/E4)>=0.8,12,IF((E17/E4)>=0.75,11,IF((E17/E4)>=0.7,10,IF((E17/E4)>=0.65,9,IF((E17/E4)>=0.6,8,IF((E17/E4)>=0.55,7,IF((E17/E4)>=0.5,6,IF((E17/E4)>=0.45,5,IF((E17/E4)>=0.4,4,IF((E17/E4)>=0.33,3,IF((E17/E4)>=0.27,2,IF((E17/E4)>=0.2,1,0)))))))))))))))) -> 12 | G17: =IF(F17>=13,1,IF(F17>=10,2,IF(F17>=7,3,IF(F17>=4,4,IF(F17>=1,5,6))))) -> 2
A18: =Stammdaten!A16&", "&Stammdaten!B16 -> Talwind, Jari | B18: 2 | C18: 3 | D18: 1.2 | E18: =SUM(B18:D18) -> 6.2 | F18: =IF(E4=0,0,IF((E18/E4)>=0.95,15,IF((E18/E4)>=0.9,14,IF((E18/E4)>=0.85,13,IF((E18/E4)>=0.8,12,IF((E18/E4)>=0.75,11,IF((E18/E4)>=0.7,10,IF((E18/E4)>=0.65,9,IF((E18/E4)>=0.6,8,IF((E18/E4)>=0.55,7,IF((E18/E4)>=0.5,6,IF((E18/E4)>=0.45,5,IF((E18/E4)>=0.4,4,IF((E18/E4)>=0.33,3,IF((E18/E4)>=0.27,2,IF((E18/E4)>=0.2,1,0)))))))))))))))) -> 13 | G18: =IF(F18>=13,1,IF(F18>=10,2,IF(F18>=7,3,IF(F18>=4,4,IF(F18>=1,5,6))))) -> 1
A19: =Stammdaten!A17&", "&Stammdaten!B17 -> Farnheim, Bino | B19: 1.89 | C19: 3 | D19: 0.2 | E19: =SUM(B19:D19) -> 5.09 | F19: =IF(E4=0,0,IF((E19/E4)>=0.95,15,IF((E19/E4)>=0.9,14,IF((E19/E4)>=0.85,13,IF((E19/E4)>=0.8,12,IF((E19/E4)>=0.75,11,IF((E19/E4)>=0.7,10,IF((E19/E4)>=0.65,9,IF((E19/E4)>=0.6,8,IF((E19/E4)>=0.55,7,IF((E19/E4)>=0.5,6,IF((E19/E4)>=0.45,5,IF((E19/E4)>=0.4,4,IF((E19/E4)>=0.33,3,IF((E19/E4)>=0.27,2,IF((E19/E4)>=0.2,1,0)))))))))))))))) -> 10 | G19: =IF(F19>=13,1,IF(F19>=10,2,IF(F19>=7,3,IF(F19>=4,4,IF(F19>=1,5,6))))) -> 2
A20: =Stammdaten!A19&", "&Stammdaten!B19 -> Tannenhof, Gina | B20: 1.94 | C20: 3 | D20: 1.2 | E20: =SUM(B20:D20) -> 6.14 | F20: =IF(E4=0,0,IF((E20/E4)>=0.95,15,IF((E20/E4)>=0.9,14,IF((E20/E4)>=0.85,13,IF((E20/E4)>=0.8,12,IF((E20/E4)>=0.75,11,IF((E20/E4)>=0.7,10,IF((E20/E4)>=0.65,9,IF((E20/E4)>=0.6,8,IF((E20/E4)>=0.55,7,IF((E20/E4)>=0.5,6,IF((E20/E4)>=0.45,5,IF((E20/E4)>=0.4,4,IF((E20/E4)>=0.33,3,IF((E20/E4)>=0.27,2,IF((E20/E4)>=0.2,1,0)))))))))))))))) -> 13 | G20: =IF(F20>=13,1,IF(F20>=10,2,IF(F20>=7,3,IF(F20>=4,4,IF(F20>=1,5,6))))) -> 1
A21: =Stammdaten!A20&", "&Stammdaten!B20 -> Lindenfels, Miro | B21: 1.94 | C21: 3 | D21: 1 | E21: =SUM(B21:D21) -> 5.94 | F21: =IF(E4=0,0,IF((E21/E4)>=0.95,15,IF((E21/E4)>=0.9,14,IF((E21/E4)>=0.85,13,IF((E21/E4)>=0.8,12,IF((E21/E4)>=0.75,11,IF((E21/E4)>=0.7,10,IF((E21/E4)>=0.65,9,IF((E21/E4)>=0.6,8,IF((E21/E4)>=0.55,7,IF((E21/E4)>=0.5,6,IF((E21/E4)>=0.45,5,IF((E21/E4)>=0.4,4,IF((E21/E4)>=0.33,3,IF((E21/E4)>=0.27,2,IF((E21/E4)>=0.2,1,0)))))))))))))))) -> 12 | G21: =IF(F21>=13,1,IF(F21>=10,2,IF(F21>=7,3,IF(F21>=4,4,IF(F21>=1,5,6))))) -> 2
A22: =Stammdaten!A21&", "&Stammdaten!B21 -> Adlerquell, Bino | B22: 2 | C22: 2.5 | D22: 0 | E22: =SUM(B22:D22) -> 4.5 | F22: =IF(E4=0,0,IF((E22/E4)>=0.95,15,IF((E22/E4)>=0.9,14,IF((E22/E4)>=0.85,13,IF((E22/E4)>=0.8,12,IF((E22/E4)>=0.75,11,IF((E22/E4)>=0.7,10,IF((E22/E4)>=0.65,9,IF((E22/E4)>=0.6,8,IF((E22/E4)>=0.55,7,IF((E22/E4)>=0.5,6,IF((E22/E4)>=0.45,5,IF((E22/E4)>=0.4,4,IF((E22/E4)>=0.33,3,IF((E22/E4)>=0.27,2,IF((E22/E4)>=0.2,1,0)))))))))))))))) -> 8 | G22: =IF(F22>=13,1,IF(F22>=10,2,IF(F22>=7,3,IF(F22>=4,4,IF(F22>=1,5,6))))) -> 3
A23: =Stammdaten!A22&", "&Stammdaten!B22 -> Bergquell, Caro | B23: 1.94 | C23: 3 | D23: 2 | E23: =SUM(B23:D23) -> 6.94 | F23: =IF(E4=0,0,IF((E23/E4)>=0.95,15,IF((E23/E4)>=0.9,14,IF((E23/E4)>=0.85,13,IF((E23/E4)>=0.8,12,IF((E23/E4)>=0.75,11,IF((E23/E4)>=0.7,10,IF((E23/E4)>=0.65,9,IF((E23/E4)>=0.6,8,IF((E23/E4)>=0.55,7,IF((E23/E4)>=0.5,6,IF((E23/E4)>=0.45,5,IF((E23/E4)>=0.4,4,IF((E23/E4)>=0.33,3,IF((E23/E4)>=0.27,2,IF((E23/E4)>=0.2,1,0)))))))))))))))) -> 15 | G23: =IF(F23>=13,1,IF(F23>=10,2,IF(F23>=7,3,IF(F23>=4,4,IF(F23>=1,5,6))))) -> 1
A24: =Stammdaten!A23&", "&Stammdaten!B23 -> Waldhauch, Gina | B24: 2 | C24: 3 | D24: 0.6 | E24: =SUM(B24:D24) -> 5.6 | F24: =IF(E4=0,0,IF((E24/E4)>=0.95,15,IF((E24/E4)>=0.9,14,IF((E24/E4)>=0.85,13,IF((E24/E4)>=0.8,12,IF((E24/E4)>=0.75,11,IF((E24/E4)>=0.7,10,IF((E24/E4)>=0.65,9,IF((E24/E4)>=0.6,8,IF((E24/E4)>=0.55,7,IF((E24/E4)>=0.5,6,IF((E24/E4)>=0.45,5,IF((E24/E4)>=0.4,4,IF((E24/E4)>=0.33,3,IF((E24/E4)>=0.27,2,IF((E24/E4)>=0.2,1,0)))))))))))))))) -> 12 | G24: =IF(F24>=13,1,IF(F24>=10,2,IF(F24>=7,3,IF(F24>=4,4,IF(F24>=1,5,6))))) -> 2
A25: =Stammdaten!A24&", "&Stammdaten!B24 -> Silbersee, Miro | B25: 2 | C25: 3 | D25: 1.6 | E25: =SUM(B25:D25) -> 6.6 | F25: =IF(E4=0,0,IF((E25/E4)>=0.95,15,IF((E25/E4)>=0.9,14,IF((E25/E4)>=0.85,13,IF((E25/E4)>=0.8,12,IF((E25/E4)>=0.75,11,IF((E25/E4)>=0.7,10,IF((E25/E4)>=0.65,9,IF((E25/E4)>=0.6,8,IF((E25/E4)>=0.55,7,IF((E25/E4)>=0.5,6,IF((E25/E4)>=0.45,5,IF((E25/E4)>=0.4,4,IF((E25/E4)>=0.33,3,IF((E25/E4)>=0.27,2,IF((E25/E4)>=0.2,1,0)))))))))))))))) -> 14 | G25: =IF(F25>=13,1,IF(F25>=10,2,IF(F25>=7,3,IF(F25>=4,4,IF(F25>=1,5,6))))) -> 1
A26: =Stammdaten!A25&", "&Stammdaten!B25 -> Winterborn, Raya | B26: 1.89 | C26: 3 | D26: 2 | E26: =SUM(B26:D26) -> 6.89 | F26: =IF(E4=0,0,IF((E26/E4)>=0.95,15,IF((E26/E4)>=0.9,14,IF((E26/E4)>=0.85,13,IF((E26/E4)>=0.8,12,IF((E26/E4)>=0.75,11,IF((E26/E4)>=0.7,10,IF((E26/E4)>=0.65,9,IF((E26/E4)>=0.6,8,IF((E26/E4)>=0.55,7,IF((E26/E4)>=0.5,6,IF((E26/E4)>=0.45,5,IF((E26/E4)>=0.4,4,IF((E26/E4)>=0.33,3,IF((E26/E4)>=0.27,2,IF((E26/E4)>=0.2,1,0)))))))))))))))) -> 15 | G26: =IF(F26>=13,1,IF(F26>=10,2,IF(F26>=7,3,IF(F26>=4,4,IF(F26>=1,5,6))))) -> 1
A27: =Stammdaten!A26&", "&Stammdaten!B26 -> Rosenquarz, Ivo | B27: 1.22 | C27: 1 | D27: 0.8 | E27: =SUM(B27:D27) -> 3.02 | F27: =IF(E4=0,0,IF((E27/E4)>=0.95,15,IF((E27/E4)>=0.9,14,IF((E27/E4)>=0.85,13,IF((E27/E4)>=0.8,12,IF((E27/E4)>=0.75,11,IF((E27/E4)>=0.7,10,IF((E27/E4)>=0.65,9,IF((E27/E4)>=0.6,8,IF((E27/E4)>=0.55,7,IF((E27/E4)>=0.5,6,IF((E27/E4)>=0.45,5,IF((E27/E4)>=0.4,4,IF((E27/E4)>=0.33,3,IF((E27/E4)>=0.27,2,IF((E27/E4)>=0.2,1,0)))))))))))))))) -> 4 | G27: =IF(F27>=13,1,IF(F27>=10,2,IF(F27>=7,3,IF(F27>=4,4,IF(F27>=1,5,6))))) -> 4
A28: =Stammdaten!A27&", "&Stammdaten!B27 -> Mondenfels, Alma | B28: 1.83 | C28: 1.5 | D28: 2 | E28: =SUM(B28:D28) -> 5.33 | F28: =IF(E4=0,0,IF((E28/E4)>=0.95,15,IF((E28/E4)>=0.9,14,IF((E28/E4)>=0.85,13,IF((E28/E4)>=0.8,12,IF((E28/E4)>=0.75,11,IF((E28/E4)>=0.7,10,IF((E28/E4)>=0.65,9,IF((E28/E4)>=0.6,8,IF((E28/E4)>=0.55,7,IF((E28/E4)>=0.5,6,IF((E28/E4)>=0.45,5,IF((E28/E4)>=0.4,4,IF((E28/E4)>=0.33,3,IF((E28/E4)>=0.27,2,IF((E28/E4)>=0.2,1,0)))))))))))))))) -> 11 | G28: =IF(F28>=13,1,IF(F28>=10,2,IF(F28>=7,3,IF(F28>=4,4,IF(F28>=1,5,6))))) -> 2
A29: =Stammdaten!A28&", "&Stammdaten!B28 -> Wolkenberg, Navi | B29: 2 | C29: 3 | D29: 2 | E29: =SUM(B29:D29) -> 7 | F29: =IF(E4=0,0,IF((E29/E4)>=0.95,15,IF((E29/E4)>=0.9,14,IF((E29/E4)>=0.85,13,IF((E29/E4)>=0.8,12,IF((E29/E4)>=0.75,11,IF((E29/E4)>=0.7,10,IF((E29/E4)>=0.65,9,IF((E29/E4)>=0.6,8,IF((E29/E4)>=0.55,7,IF((E29/E4)>=0.5,6,IF((E29/E4)>=0.45,5,IF((E29/E4)>=0.4,4,IF((E29/E4)>=0.33,3,IF((E29/E4)>=0.27,2,IF((E29/E4)>=0.2,1,0)))))))))))))))) -> 15 | G29: =IF(F29>=13,1,IF(F29>=10,2,IF(F29>=7,3,IF(F29>=4,4,IF(F29>=1,5,6))))) -> 1
A30: =Stammdaten!A29&", "&Stammdaten!B29 -> Nordlicht, Navi | B30: 2 | C30: 2.5 | D30: 0 | E30: =SUM(B30:D30) -> 4.5 | F30: =IF(E4=0,0,IF((E30/E4)>=0.95,15,IF((E30/E4)>=0.9,14,IF((E30/E4)>=0.85,13,IF((E30/E4)>=0.8,12,IF((E30/E4)>=0.75,11,IF((E30/E4)>=0.7,10,IF((E30/E4)>=0.65,9,IF((E30/E4)>=0.6,8,IF((E30/E4)>=0.55,7,IF((E30/E4)>=0.5,6,IF((E30/E4)>=0.45,5,IF((E30/E4)>=0.4,4,IF((E30/E4)>=0.33,3,IF((E30/E4)>=0.27,2,IF((E30/E4)>=0.2,1,0)))))))))))))))) -> 8 | G30: =IF(F30>=13,1,IF(F30>=10,2,IF(F30>=7,3,IF(F30>=4,4,IF(F30>=1,5,6))))) -> 3
A31: =Stammdaten!A30&", "&Stammdaten!B30 -> Lindenfels, Hedi | B31: 1.89 | C31: 0.5 | D31: 0.2 | E31: =SUM(B31:D31) -> 2.59 | F31: =IF(E4=0,0,IF((E31/E4)>=0.95,15,IF((E31/E4)>=0.9,14,IF((E31/E4)>=0.85,13,IF((E31/E4)>=0.8,12,IF((E31/E4)>=0.75,11,IF((E31/E4)>=0.7,10,IF((E31/E4)>=0.65,9,IF((E31/E4)>=0.6,8,IF((E31/E4)>=0.55,7,IF((E31/E4)>=0.5,6,IF((E31/E4)>=0.45,5,IF((E31/E4)>=0.4,4,IF((E31/E4)>=0.33,3,IF((E31/E4)>=0.27,2,IF((E31/E4)>=0.2,1,0)))))))))))))))) -> 3 | G31: =IF(F31>=13,1,IF(F31>=10,2,IF(F31>=7,3,IF(F31>=4,4,IF(F31>=1,5,6))))) -> 5

Sheet LN_SÜ Krypto
A1: LN_TYP | B1: GLN | C1: HJ | D1: HJ2 | E1: SL_ZUORDNUNG | G1: GLN_SLOT | I1: NACHTERMIN_VON | K1: NOTEN_RUNDEN | L1: 1
A2: Schüler | B2: 1 | C2: 2 | D2: 3 | E2: 4 | F2: 5 | G2: 6 | H2: 7 | I2: 8 | J2: 9 | K2: 10 | L2: Gesamt | M2: Note (0-15) | N2: Note (1-6) | O2: Ignoriert
A3: Anforderungsbereich
A4: Max. Punkte | B4: 3 | C4: 2 | D4: 2 | E4: 2 | F4: 3 | G4: 3 | H4: 3 | I4: 3 | J4: 2 | K4: 2 | L4: =SUM(B4:K4) -> 25
A5: =Stammdaten!A3&", "&Stammdaten!B3 -> Farnheim, Goro | B5: 2.6 | C5: 0 | D5: 0.5 | E5: 0.4 | F5: 0.75 | G5: 3 | H5: 2.31 | I5: 1.5 | J5: 0 | K5: 0 | L5: =SUM(B5:K5) -> 11.06 | M5: =IF(L4=0,0,IF((L5/L4)>=0.95,15,IF((L5/L4)>=0.9,14,IF((L5/L4)>=0.85,13,IF((L5/L4)>=0.8,12,IF((L5/L4)>=0.75,11,IF((L5/L4)>=0.7,10,IF((L5/L4)>=0.65,9,IF((L5/L4)>=0.6,8,IF((L5/L4)>=0.55,7,IF((L5/L4)>=0.5,6,IF((L5/L4)>=0.45,5,IF((L5/L4)>=0.4,4,IF((L5/L4)>=0.33,3,IF((L5/L4)>=0.27,2,IF((L5/L4)>=0.2,1,0)))))))))))))))) -> 4 | N5: =IF(M5>=13,1,IF(M5>=10,2,IF(M5>=7,3,IF(M5>=4,4,IF(M5>=1,5,6))))) -> 4
A6: =Stammdaten!A4&", "&Stammdaten!B4 -> Silbersee, Caro | B6: 2.9 | C6: 0 | D6: 2 | E6: 0.8 | F6: 1.31 | G6: 3 | H6: 3 | I6: 3 | J6: 0 | K6: 1.1 | L6: =SUM(B6:K6) -> 17.11 | M6: =IF(L4=0,0,IF((L6/L4)>=0.95,15,IF((L6/L4)>=0.9,14,IF((L6/L4)>=0.85,13,IF((L6/L4)>=0.8,12,IF((L6/L4)>=0.75,11,IF((L6/L4)>=0.7,10,IF((L6/L4)>=0.65,9,IF((L6/L4)>=0.6,8,IF((L6/L4)>=0.55,7,IF((L6/L4)>=0.5,6,IF((L6/L4)>=0.45,5,IF((L6/L4)>=0.4,4,IF((L6/L4)>=0.33,3,IF((L6/L4)>=0.27,2,IF((L6/L4)>=0.2,1,0)))))))))))))))) -> 9 | N6: =IF(M6>=13,1,IF(M6>=10,2,IF(M6>=7,3,IF(M6>=4,4,IF(M6>=1,5,6))))) -> 3
A7: =Stammdaten!A5&", "&Stammdaten!B5 -> Adlerquell, Weya | B7: 15 | L7: =SUM(B7:K7) -> 15 | M7: =IF(L4=0,0,IF((L7/L4)>=0.95,15,IF((L7/L4)>=0.9,14,IF((L7/L4)>=0.85,13,IF((L7/L4)>=0.8,12,IF((L7/L4)>=0.75,11,IF((L7/L4)>=0.7,10,IF((L7/L4)>=0.65,9,IF((L7/L4)>=0.6,8,IF((L7/L4)>=0.55,7,IF((L7/L4)>=0.5,6,IF((L7/L4)>=0.45,5,IF((L7/L4)>=0.4,4,IF((L7/L4)>=0.33,3,IF((L7/L4)>=0.27,2,IF((L7/L4)>=0.2,1,0)))))))))))))))) -> 8 | N7: =IF(M7>=13,1,IF(M7>=10,2,IF(M7>=7,3,IF(M7>=4,4,IF(M7>=1,5,6))))) -> 3
A8: =Stammdaten!A6&", "&Stammdaten!B6 -> Talwind, Demi | B8: 3 | C8: 2 | D8: 1.75 | E8: 1.2 | F8: 2.91 | G8: 3 | H8: 3 | I8: 2.7 | J8: 0.5 | K8: 1 | L8: =SUM(B8:K8) -> 21.06 | M8: =IF(L4=0,0,IF((L8/L4)>=0.95,15,IF((L8/L4)>=0.9,14,IF((L8/L4)>=0.85,13,IF((L8/L4)>=0.8,12,IF((L8/L4)>=0.75,11,IF((L8/L4)>=0.7,10,IF((L8/L4)>=0.65,9,IF((L8/L4)>=0.6,8,IF((L8/L4)>=0.55,7,IF((L8/L4)>=0.5,6,IF((L8/L4)>=0.45,5,IF((L8/L4)>=0.4,4,IF((L8/L4)>=0.33,3,IF((L8/L4)>=0.27,2,IF((L8/L4)>=0.2,1,0)))))))))))))))) -> 12 | N8: =IF(M8>=13,1,IF(M8>=10,2,IF(M8>=7,3,IF(M8>=4,4,IF(M8>=1,5,6))))) -> 2
A9: =Stammdaten!A7&", "&Stammdaten!B7 -> Nachtigall, Alma | B9: 2.8 | C9: 2 | D9: 0.5 | E9: 1.2 | F9: 1.5 | G9: 2.7 | H9: 3 | I9: 3 | J9: 2 | K9: 1 | L9: =SUM(B9:K9) -> 19.7 | M9: =IF(L4=0,0,IF((L9/L4)>=0.95,15,IF((L9/L4)>=0.9,14,IF((L9/L4)>=0.85,13,IF((L9/L4)>=0.8,12,IF((L9/L4)>=0.75,11,IF((L9/L4)>=0.7,10,IF((L9/L4)>=0.65,9,IF((L9/L4)>=0.6,8,IF((L9/L4)>=0.55,7,IF((L9/L4)>=0.5,6,IF((L9/L4)>=0.45,5,IF((L9/L4)>=0.4,4,IF((L9/L4)>=0.33,3,IF((L9/L4)>=0.27,2,IF((L9/L4)>=0.2,1,0)))))))))))))))) -> 11 | N9: =IF(M9>=13,1,IF(M9>=10,2,IF(M9>=7,3,IF(M9>=4,4,IF(M9>=1,5,6))))) -> 2
A10: =Stammdaten!A8&", "&Stammdaten!B8 -> Kieselhain, Tino | B10: 2.6 | C10: 2 | D10: 1.5 | E10: 1.2 | F10: 2.25 | G10: 3 | H10: 3 | I10: 3 | J10: 2 | K10: 1.6 | L10: =SUM(B10:K10) -> 22.15 | M10: =IF(L4=0,0,IF((L10/L4)>=0.95,15,IF((L10/L4)>=0.9,14,IF((L10/L4)>=0.85,13,IF((L10/L4)>=0.8,12,IF((L10/L4)>=0.75,11,IF((L10/L4)>=0.7,10,IF((L10/L4)>=0.65,9,IF((L10/L4)>=0.6,8,IF((L10/L4)>=0.55,7,IF((L10/L4)>=0.5,6,IF((L10/L4)>=0.45,5,IF((L10/L4)>=0.4,4,IF((L10/L4)>=0.33,3,IF((L10/L4)>=0.27,2,IF((L10/L4)>=0.2,1,0)))))))))))))))) -> 13 | N10: =IF(M10>=13,1,IF(M10>=10,2,IF(M10>=7,3,IF(M10>=4,4,IF(M10>=1,5,6))))) -> 1
A11: =Stammdaten!A9&", "&Stammdaten!B9 -> Talwind, Goro | B11: 3 | C11: 2 | D11: 0.5 | E11: 0 | F11: 2.25 | G11: 0 | H11: 2.54 | I11: 0.6 | J11: 0 | K11: 1 | L11: =SUM(B11:K11) -> 11.89 | M11: =IF(L4=0,0,IF((L11/L4)>=0.95,15,IF((L11/L4)>=0.9,14,IF((L11/L4)>=0.85,13,IF((L11/L4)>=0.8,12,IF((L11/L4)>=0.75,11,IF((L11/L4)>=0.7,10,IF((L11/L4)>=0.65,9,IF((L11/L4)>=0.6,8,IF((L11/L4)>=0.55,7,IF((L11/L4)>=0.5,6,IF((L11/L4)>=0.45,5,IF((L11/L4)>=0.4,4,IF((L11/L4)>=0.33,3,IF((L11/L4)>=0.27,2,IF((L11/L4)>=0.2,1,0)))))))))))))))) -> 5 | N11: =IF(M11>=13,1,IF(M11>=10,2,IF(M11>=7,3,IF(M11>=4,4,IF(M11>=1,5,6))))) -> 4
A12: =Stammdaten!A10&", "&Stammdaten!B10 -> Kornfeld, Nerio | B12: 3 | C12: 2 | D12: 1.75 | E12: 0.8 | F12: 3 | G12: 3 | H12: 3 | I12: 3 | J12: 0 | K12: 0 | L12: =SUM(B12:K12) -> 19.55 | M12: =IF(L4=0,0,IF((L12/L4)>=0.95,15,IF((L12/L4)>=0.9,14,IF((L12/L4)>=0.85,13,IF((L12/L4)>=0.8,12,IF((L12/L4)>=0.75,11,IF((L12/L4)>=0.7,10,IF((L12/L4)>=0.65,9,IF((L12/L4)>=0.6,8,IF((L12/L4)>=0.55,7,IF((L12/L4)>=0.5,6,IF((L12/L4)>=0.45,5,IF((L12/L4)>=0.4,4,IF((L12/L4)>=0.33,3,IF((L12/L4)>=0.27,2,IF((L12/L4)>=0.2,1,0)))))))))))))))) -> 11 | N12: =IF(M12>=13,1,IF(M12>=10,2,IF(M12>=7,3,IF(M12>=4,4,IF(M12>=1,5,6))))) -> 2
A13: =Stammdaten!A11&", "&Stammdaten!B11 -> Rosenquarz, Vito | B13: 1.7 | C13: 0 | D13: 0.25 | E13: 0 | F13: 2.63 | G13: 3 | H13: 3 | I13: 3 | J13: 0 | K13: 0 | L13: =SUM(B13:K13) -> 13.58 | M13: =IF(L4=0,0,IF((L13/L4)>=0.95,15,IF((L13/L4)>=0.9,14,IF((L13/L4)>=0.85,13,IF((L13/L4)>=0.8,12,IF((L13/L4)>=0.75,11,IF((L13/L4)>=0.7,10,IF((L13/L4)>=0.65,9,IF((L13/L4)>=0.6,8,IF((L13/L4)>=0.55,7,IF((L13/L4)>=0.5,6,IF((L13/L4)>=0.45,5,IF((L13/L4)>=0.4,4,IF((L13/L4)>=0.33,3,IF((L13/L4)>=0.27,2,IF((L13/L4)>=0.2,1,0)))))))))))))))) -> 6 | N13: =IF(M13>=13,1,IF(M13>=10,2,IF(M13>=7,3,IF(M13>=4,4,IF(M13>=1,5,6))))) -> 4
A14: =Stammdaten!A12&", "&Stammdaten!B12 -> Seidenberg, Miro | B14: 2.3 | C14: 0 | D14: 0.25 | E14: 0.4 | F14: 0.75 | G14: 0 | H14: 1.38 | I14: 2.7 | J14: 0 | K14: 0 | L14: =SUM(B14:K14) -> 7.78 | M14: =IF(L4=0,0,IF((L14/L4)>=0.95,15,IF((L14/L4)>=0.9,14,IF((L14/L4)>=0.85,13,IF((L14/L4)>=0.8,12,IF((L14/L4)>=0.75,11,IF((L14/L4)>=0.7,10,IF((L14/L4)>=0.65,9,IF((L14/L4)>=0.6,8,IF((L14/L4)>=0.55,7,IF((L14/L4)>=0.5,6,IF((L14/L4)>=0.45,5,IF((L14/L4)>=0.4,4,IF((L14/L4)>=0.33,3,IF((L14/L4)>=0.27,2,IF((L14/L4)>=0.2,1,0)))))))))))))))) -> 2 | N14: =IF(M14>=13,1,IF(M14>=10,2,IF(M14>=7,3,IF(M14>=4,4,IF(M14>=1,5,6))))) -> 5
A15: =Stammdaten!A13&", "&Stammdaten!B13 -> Kieselhain, Pia | B15: 2.5 | C15: 2 | D15: 1.5 | E15: 0.8 | F15: 1.41 | G15: 3 | H15: 0.46 | I15: 3 | J15: 2 | K15: 0 | L15: =SUM(B15:K15) -> 16.67 | M15: =IF(L4=0,0,IF((L15/L4)>=0.95,15,IF((L15/L4)>=0.9,14,IF((L15/L4)>=0.85,13,IF((L15/L4)>=0.8,12,IF((L15/L4)>=0.75,11,IF((L15/L4)>=0.7,10,IF((L15/L4)>=0.65,9,IF((L15/L4)>=0.6,8,IF((L15/L4)>=0.55,7,IF((L15/L4)>=0.5,6,IF((L15/L4)>=0.45,5,IF((L15/L4)>=0.4,4,IF((L15/L4)>=0.33,3,IF((L15/L4)>=0.27,2,IF((L15/L4)>=0.2,1,0)))))))))))))))) -> 9 | N15: =IF(M15>=13,1,IF(M15>=10,2,IF(M15>=7,3,IF(M15>=4,4,IF(M15>=1,5,6))))) -> 3
A16: =Stammdaten!A14&", "&Stammdaten!B14 -> Blaustein, Miro | B16: 2.4 | C16: 2 | D16: 1.75 | E16: 0.8 | F16: 3 | G16: 3 | H16: 3 | I16: 3 | J16: 2 | K16: 0 | L16: =SUM(B16:K16) -> 20.95 | M16: =IF(L4=0,0,IF((L16/L4)>=0.95,15,IF((L16/L4)>=0.9,14,IF((L16/L4)>=0.85,13,IF((L16/L4)>=0.8,12,IF((L16/L4)>=0.75,11,IF((L16/L4)>=0.7,10,IF((L16/L4)>=0.65,9,IF((L16/L4)>=0.6,8,IF((L16/L4)>=0.55,7,IF((L16/L4)>=0.5,6,IF((L16/L4)>=0.45,5,IF((L16/L4)>=0.4,4,IF((L16/L4)>=0.33,3,IF((L16/L4)>=0.27,2,IF((L16/L4)>=0.2,1,0)))))))))))))))) -> 12 | N16: =IF(M16>=13,1,IF(M16>=10,2,IF(M16>=7,3,IF(M16>=4,4,IF(M16>=1,5,6))))) -> 2
A17: =Stammdaten!A15&", "&Stammdaten!B15 -> Bergquell, Ari | B17: 2.8 | C17: 0 | D17: 0.25 | E17: 0 | F17: 1.5 | G17: 3 | H17: 1.38 | I17: 0.99 | J17: 1.5 | K17: 0 | L17: =SUM(B17:K17) -> 11.42 | M17: =IF(L4=0,0,IF((L17/L4)>=0.95,15,IF((L17/L4)>=0.9,14,IF((L17/L4)>=0.85,13,IF((L17/L4)>=0.8,12,IF((L17/L4)>=0.75,11,IF((L17/L4)>=0.7,10,IF((L17/L4)>=0.65,9,IF((L17/L4)>=0.6,8,IF((L17/L4)>=0.55,7,IF((L17/L4)>=0.5,6,IF((L17/L4)>=0.45,5,IF((L17/L4)>=0.4,4,IF((L17/L4)>=0.33,3,IF((L17/L4)>=0.27,2,IF((L17/L4)>=0.2,1,0)))))))))))))))) -> 5 | N17: =IF(M17>=13,1,IF(M17>=10,2,IF(M17>=7,3,IF(M17>=4,4,IF(M17>=1,5,6))))) -> 4
A18: =Stammdaten!A16&", "&Stammdaten!B16 -> Talwind, Jari | B18: 2.5 | C18: 2 | D18: 2 | E18: 1.6 | F18: 2.25 | G18: 3 | H18: 3 | I18: 3 | J18: 1.5 | K18: 1.3 | L18: =SUM(B18:K18) -> 22.15 | M18: =IF(L4=0,0,IF((L18/L4)>=0.95,15,IF((L18/L4)>=0.9,14,IF((L18/L4)>=0.85,13,IF((L18/L4)>=0.8,12,IF((L18/L4)>=0.75,11,IF((L18/L4)>=0.7,10,IF((L18/L4)>=0.65,9,IF((L18/L4)>=0.6,8,IF((L18/L4)>=0.55,7,IF((L18/L4)>=0.5,6,IF((L18/L4)>=0.45,5,IF((L18/L4)>=0.4,4,IF((L18/L4)>=0.33,3,IF((L18/L4)>=0.27,2,IF((L18/L4)>=0.2,1,0)))))))))))))))) -> 13 | N18: =IF(M18>=13,1,IF(M18>=10,2,IF(M18>=7,3,IF(M18>=4,4,IF(M18>=1,5,6))))) -> 1
A19: =Stammdaten!A17&", "&Stammdaten!B17 -> Farnheim, Bino | B19: 2.4 | C19: 2 | D19: 0.25 | E19: 0.4 | F19: 1.13 | G19: 3 | H19: 3 | I19: 0 | J19: 0 | K19: 1 | L19: =SUM(B19:K19) -> 13.18 | M19: =IF(L4=0,0,IF((L19/L4)>=0.95,15,IF((L19/L4)>=0.9,14,IF((L19/L4)>=0.85,13,IF((L19/L4)>=0.8,12,IF((L19/L4)>=0.75,11,IF((L19/L4)>=0.7,10,IF((L19/L4)>=0.65,9,IF((L19/L4)>=0.6,8,IF((L19/L4)>=0.55,7,IF((L19/L4)>=0.5,6,IF((L19/L4)>=0.45,5,IF((L19/L4)>=0.4,4,IF((L19/L4)>=0.33,3,IF((L19/L4)>=0.27,2,IF((L19/L4)>=0.2,1,0)))))))))))))))) -> 6 | N19: =IF(M19>=13,1,IF(M19>=10,2,IF(M19>=7,3,IF(M19>=4,4,IF(M19>=1,5,6))))) -> 4
A20: =Stammdaten!A19&", "&Stammdaten!B19 -> Tannenhof, Gina | B20: 3 | C20: 2 | D20: 1.75 | E20: 0.8 | F20: 1.5 | G20: 3 | H20: 2.31 | I20: 0.3 | J20: 1.5 | K20: 0 | L20: =SUM(B20:K20) -> 16.16 | M20: =IF(L4=0,0,IF((L20/L4)>=0.95,15,IF((L20/L4)>=0.9,14,IF((L20/L4)>=0.85,13,IF((L20/L4)>=0.8,12,IF((L20/L4)>=0.75,11,IF((L20/L4)>=0.7,10,IF((L20/L4)>=0.65,9,IF((L20/L4)>=0.6,8,IF((L20/L4)>=0.55,7,IF((L20/L4)>=0.5,6,IF((L20/L4)>=0.45,5,IF((L20/L4)>=0.4,4,IF((L20/L4)>=0.33,3,IF((L20/L4)>=0.27,2,IF((L20/L4)>=0.2,1,0)))))))))))))))) -> 8 | N20: =IF(M20>=13,1,IF(M20>=10,2,IF(M20>=7,3,IF(M20>=4,4,IF(M20>=1,5,6))))) -> 3
A21: =Stammdaten!A20&", "&Stammdaten!B20 -> Lindenfels, Miro | B21: 3 | C21: 2 | D21: 0.5 | E21: 0.4 | F21: 1.41 | G21: 3 | H21: 2.54 | I21: 0 | J21: 0 | K21: 0 | L21: =SUM(B21:K21) -> 12.85 | M21: =IF(L4=0,0,IF((L21/L4)>=0.95,15,IF((L21/L4)>=0.9,14,IF((L21/L4)>=0.85,13,IF((L21/L4)>=0.8,12,IF((L21/L4)>=0.75,11,IF((L21/L4)>=0.7,10,IF((L21/L4)>=0.65,9,IF((L21/L4)>=0.6,8,IF((L21/L4)>=0.55,7,IF((L21/L4)>=0.5,6,IF((L21/L4)>=0.45,5,IF((L21/L4)>=0.4,4,IF((L21/L4)>=0.33,3,IF((L21/L4)>=0.27,2,IF((L21/L4)>=0.2,1,0)))))))))))))))) -> 6 | N21: =IF(M21>=13,1,IF(M21>=10,2,IF(M21>=7,3,IF(M21>=4,4,IF(M21>=1,5,6))))) -> 4
A22: =Stammdaten!A21&", "&Stammdaten!B21 -> Adlerquell, Bino | B22: 2.8 | C22: 2 | D22: 0.5 | E22: 0 | F22: 2.81 | G22: 3 | H22: 3 | I22: 3 | J22: 2 | K22: 1.8 | L22: =SUM(B22:K22) -> 20.91 | M22: =IF(L4=0,0,IF((L22/L4)>=0.95,15,IF((L22/L4)>=0.9,14,IF((L22/L4)>=0.85,13,IF((L22/L4)>=0.8,12,IF((L22/L4)>=0.75,11,IF((L22/L4)>=0.7,10,IF((L22/L4)>=0.65,9,IF((L22/L4)>=0.6,8,IF((L22/L4)>=0.55,7,IF((L22/L4)>=0.5,6,IF((L22/L4)>=0.45,5,IF((L22/L4)>=0.4,4,IF((L22/L4)>=0.33,3,IF((L22/L4)>=0.27,2,IF((L22/L4)>=0.2,1,0)))))))))))))))) -> 12 | N22: =IF(M22>=13,1,IF(M22>=10,2,IF(M22>=7,3,IF(M22>=4,4,IF(M22>=1,5,6))))) -> 2
A23: =Stammdaten!A22&", "&Stammdaten!B22 -> Bergquell, Caro | B23: 1.7 | C23: 2 | D23: 1.5 | E23: 0.4 | F23: 1.13 | G23: 3 | H23: 0.92 | I23: 0.3 | J23: 0 | K23: 0 | L23: =SUM(B23:K23) -> 10.95 | M23: =IF(L4=0,0,IF((L23/L4)>=0.95,15,IF((L23/L4)>=0.9,14,IF((L23/L4)>=0.85,13,IF((L23/L4)>=0.8,12,IF((L23/L4)>=0.75,11,IF((L23/L4)>=0.7,10,IF((L23/L4)>=0.65,9,IF((L23/L4)>=0.6,8,IF((L23/L4)>=0.55,7,IF((L23/L4)>=0.5,6,IF((L23/L4)>=0.45,5,IF((L23/L4)>=0.4,4,IF((L23/L4)>=0.33,3,IF((L23/L4)>=0.27,2,IF((L23/L4)>=0.2,1,0)))))))))))))))) -> 4 | N23: =IF(M23>=13,1,IF(M23>=10,2,IF(M23>=7,3,IF(M23>=4,4,IF(M23>=1,5,6))))) -> 4
A24: =Stammdaten!A23&", "&Stammdaten!B23 -> Waldhauch, Gina | B24: 2.6 | C24: 2 | D24: 1.88 | E24: 1.6 | F24: 3 | G24: 3 | H24: 3 | I24: 3 | J24: 2 | K24: 1.3 | L24: =SUM(B24:K24) -> 23.38 | M24: =IF(L4=0,0,IF((L24/L4)>=0.95,15,IF((L24/L4)>=0.9,14,IF((L24/L4)>=0.85,13,IF((L24/L4)>=0.8,12,IF((L24/L4)>=0.75,11,IF((L24/L4)>=0.7,10,IF((L24/L4)>=0.65,9,IF((L24/L4)>=0.6,8,IF((L24/L4)>=0.55,7,IF((L24/L4)>=0.5,6,IF((L24/L4)>=0.45,5,IF((L24/L4)>=0.4,4,IF((L24/L4)>=0.33,3,IF((L24/L4)>=0.27,2,IF((L24/L4)>=0.2,1,0)))))))))))))))) -> 14 | N24: =IF(M24>=13,1,IF(M24>=10,2,IF(M24>=7,3,IF(M24>=4,4,IF(M24>=1,5,6))))) -> 1
A25: =Stammdaten!A24&", "&Stammdaten!B24 -> Silbersee, Miro | B25: 3 | C25: 2 | D25: 1 | E25: 2 | F25: 2.81 | G25: 3 | H25: 3 | I25: 3 | J25: 2 | K25: 2 | L25: =SUM(B25:K25) -> 23.81 | M25: =IF(L4=0,0,IF((L25/L4)>=0.95,15,IF((L25/L4)>=0.9,14,IF((L25/L4)>=0.85,13,IF((L25/L4)>=0.8,12,IF((L25/L4)>=0.75,11,IF((L25/L4)>=0.7,10,IF((L25/L4)>=0.65,9,IF((L25/L4)>=0.6,8,IF((L25/L4)>=0.55,7,IF((L25/L4)>=0.5,6,IF((L25/L4)>=0.45,5,IF((L25/L4)>=0.4,4,IF((L25/L4)>=0.33,3,IF((L25/L4)>=0.27,2,IF((L25/L4)>=0.2,1,0)))))))))))))))) -> 15 | N25: =IF(M25>=13,1,IF(M25>=10,2,IF(M25>=7,3,IF(M25>=4,4,IF(M25>=1,5,6))))) -> 1
A26: =Stammdaten!A25&", "&Stammdaten!B25 -> Winterborn, Raya | B26: 2.8 | C26: 2 | D26: 1 | E26: 2 | F26: 2.91 | G26: 3 | H26: 3 | I26: 3 | J26: 2 | K26: 1.6 | L26: =SUM(B26:K26) -> 23.31 | M26: =IF(L4=0,0,IF((L26/L4)>=0.95,15,IF((L26/L4)>=0.9,14,IF((L26/L4)>=0.85,13,IF((L26/L4)>=0.8,12,IF((L26/L4)>=0.75,11,IF((L26/L4)>=0.7,10,IF((L26/L4)>=0.65,9,IF((L26/L4)>=0.6,8,IF((L26/L4)>=0.55,7,IF((L26/L4)>=0.5,6,IF((L26/L4)>=0.45,5,IF((L26/L4)>=0.4,4,IF((L26/L4)>=0.33,3,IF((L26/L4)>=0.27,2,IF((L26/L4)>=0.2,1,0)))))))))))))))) -> 14 | N26: =IF(M26>=13,1,IF(M26>=10,2,IF(M26>=7,3,IF(M26>=4,4,IF(M26>=1,5,6))))) -> 1
A27: =Stammdaten!A26&", "&Stammdaten!B26 -> Rosenquarz, Ivo | B27: 2.2 | C27: 2 | D27: 0.5 | E27: 0.4 | F27: 1.22 | G27: 3 | H27: 3 | I27: 0.6 | J27: 0 | K27: 0 | L27: =SUM(B27:K27) -> 12.92 | M27: =IF(L4=0,0,IF((L27/L4)>=0.95,15,IF((L27/L4)>=0.9,14,IF((L27/L4)>=0.85,13,IF((L27/L4)>=0.8,12,IF((L27/L4)>=0.75,11,IF((L27/L4)>=0.7,10,IF((L27/L4)>=0.65,9,IF((L27/L4)>=0.6,8,IF((L27/L4)>=0.55,7,IF((L27/L4)>=0.5,6,IF((L27/L4)>=0.45,5,IF((L27/L4)>=0.4,4,IF((L27/L4)>=0.33,3,IF((L27/L4)>=0.27,2,IF((L27/L4)>=0.2,1,0)))))))))))))))) -> 6 | N27: =IF(M27>=13,1,IF(M27>=10,2,IF(M27>=7,3,IF(M27>=4,4,IF(M27>=1,5,6))))) -> 4
A28: =Stammdaten!A27&", "&Stammdaten!B27 -> Mondenfels, Alma | B28: 2.5 | C28: 2 | D28: 1.75 | E28: 0.8 | F28: 2.25 | G28: 3 | H28: 3 | I28: 3 | J28: 2 | K28: 2 | L28: =SUM(B28:K28) -> 22.3 | M28: =IF(L4=0,0,IF((L28/L4)>=0.95,15,IF((L28/L4)>=0.9,14,IF((L28/L4)>=0.85,13,IF((L28/L4)>=0.8,12,IF((L28/L4)>=0.75,11,IF((L28/L4)>=0.7,10,IF((L28/L4)>=0.65,9,IF((L28/L4)>=0.6,8,IF((L28/L4)>=0.55,7,IF((L28/L4)>=0.5,6,IF((L28/L4)>=0.45,5,IF((L28/L4)>=0.4,4,IF((L28/L4)>=0.33,3,IF((L28/L4)>=0.27,2,IF((L28/L4)>=0.2,1,0)))))))))))))))) -> 13 | N28: =IF(M28>=13,1,IF(M28>=10,2,IF(M28>=7,3,IF(M28>=4,4,IF(M28>=1,5,6))))) -> 1
A29: =Stammdaten!A28&", "&Stammdaten!B28 -> Wolkenberg, Navi | B29: 3 | C29: 2 | D29: 1 | E29: 1.6 | F29: 1.5 | G29: 3 | H29: 3 | I29: 3 | J29: 2 | K29: 0 | L29: =SUM(B29:K29) -> 20.1 | M29: =IF(L4=0,0,IF((L29/L4)>=0.95,15,IF((L29/L4)>=0.9,14,IF((L29/L4)>=0.85,13,IF((L29/L4)>=0.8,12,IF((L29/L4)>=0.75,11,IF((L29/L4)>=0.7,10,IF((L29/L4)>=0.65,9,IF((L29/L4)>=0.6,8,IF((L29/L4)>=0.55,7,IF((L29/L4)>=0.5,6,IF((L29/L4)>=0.45,5,IF((L29/L4)>=0.4,4,IF((L29/L4)>=0.33,3,IF((L29/L4)>=0.27,2,IF((L29/L4)>=0.2,1,0)))))))))))))))) -> 12 | N29: =IF(M29>=13,1,IF(M29>=10,2,IF(M29>=7,3,IF(M29>=4,4,IF(M29>=1,5,6))))) -> 2
A30: =Stammdaten!A29&", "&Stammdaten!B29 -> Nordlicht, Navi | B30: 2.4 | C30: 2 | D30: 0 | E30: 1.2 | F30: 2.63 | G30: 0 | H30: 3 | I30: 3 | J30: 2 | K30: 0 | L30: =SUM(B30:K30) -> 16.23 | M30: =IF(L4=0,0,IF((L30/L4)>=0.95,15,IF((L30/L4)>=0.9,14,IF((L30/L4)>=0.85,13,IF((L30/L4)>=0.8,12,IF((L30/L4)>=0.75,11,IF((L30/L4)>=0.7,10,IF((L30/L4)>=0.65,9,IF((L30/L4)>=0.6,8,IF((L30/L4)>=0.55,7,IF((L30/L4)>=0.5,6,IF((L30/L4)>=0.45,5,IF((L30/L4)>=0.4,4,IF((L30/L4)>=0.33,3,IF((L30/L4)>=0.27,2,IF((L30/L4)>=0.2,1,0)))))))))))))))) -> 8 | N30: =IF(M30>=13,1,IF(M30>=10,2,IF(M30>=7,3,IF(M30>=4,4,IF(M30>=1,5,6))))) -> 3
A31: =Stammdaten!A30&", "&Stammdaten!B30 -> Lindenfels, Hedi | B31: 2.8 | C31: 2 | D31: 1.88 | E31: 2 | F31: 3 | G31: 3 | H31: 3 | I31: 3 | J31: 2 | K31: 0.5 | L31: =SUM(B31:K31) -> 23.18 | M31: =IF(L4=0,0,IF((L31/L4)>=0.95,15,IF((L31/L4)>=0.9,14,IF((L31/L4)>=0.85,13,IF((L31/L4)>=0.8,12,IF((L31/L4)>=0.75,11,IF((L31/L4)>=0.7,10,IF((L31/L4)>=0.65,9,IF((L31/L4)>=0.6,8,IF((L31/L4)>=0.55,7,IF((L31/L4)>=0.5,6,IF((L31/L4)>=0.45,5,IF((L31/L4)>=0.4,4,IF((L31/L4)>=0.33,3,IF((L31/L4)>=0.27,2,IF((L31/L4)>=0.2,1,0)))))))))))))))) -> 14 | N31: =IF(M31>=13,1,IF(M31>=10,2,IF(M31>=7,3,IF(M31>=4,4,IF(M31>=1,5,6))))) -> 1

Sheet Noten_HJ1
A1: Schüler | B1: GLN1 | C1: Ø (gewichtet) | D1: Zeugnisnote | E1: Verhalten | F1: Mitarbeit
A2: =Stammdaten!A3&", "&Stammdaten!B3 -> Farnheim, Goro | B2: =LN_GLN1!C5 -> 0 | C2: =AVERAGE(B2:B2) -> 0 | D2: =ROUND(C2,0) -> 0 | E2: 1 | F2: 2
A3: =Stammdaten!A4&", "&Stammdaten!B4 -> Silbersee, Caro | B3: =LN_GLN1!C6 -> 0 | C3: =AVERAGE(B3:B3) -> 0 | D3: =ROUND(C3,0) -> 0 | F3: 3
A4: =Stammdaten!A5&", "&Stammdaten!B5 -> Adlerquell, Weya | B4: =LN_GLN1!C7 -> 0 | C4: =AVERAGE(B4:B4) -> 0 | D4: =ROUND(C4,0) -> 0 | E4: 2 | F4: 2
A5: =Stammdaten!A6&", "&Stammdaten!B6 -> Talwind, Demi | B5: =LN_GLN1!C8 -> 0 | C5: =AVERAGE(B5:B5) -> 0 | D5: =ROUND(C5,0) -> 0 | E5: 2 | F5: 1
A6: =Stammdaten!A7&", "&Stammdaten!B7 -> Nachtigall, Alma | B6: =LN_GLN1!C9 -> 0 | C6: =AVERAGE(B6:B6) -> 0 | D6: =ROUND(C6,0) -> 0 | E6: 1 | F6: 2
A7: =Stammdaten!A8&", "&Stammdaten!B8 -> Kieselhain, Tino | B7: =LN_GLN1!C10 -> 0 | C7: =AVERAGE(B7:B7) -> 0 | D7: =ROUND(C7,0) -> 0 | E7: 1 | F7: 2
A8: =Stammdaten!A9&", "&Stammdaten!B9 -> Talwind, Goro | B8: =LN_GLN1!C11 -> 0 | C8: =AVERAGE(B8:B8) -> 0 | D8: =ROUND(C8,0) -> 0 | E8: 1 | F8: 1
A9: =Stammdaten!A10&", "&Stammdaten!B10 -> Kornfeld, Nerio | B9: =LN_GLN1!C12 -> 0 | C9: =AVERAGE(B9:B9) -> 0 | D9: =ROUND(C9,0) -> 0 | E9: 2 | F9: 2
A10: =Stammdaten!A11&", "&Stammdaten!B11 -> Rosenquarz, Vito | B10: =LN_GLN1!C13 -> 0 | C10: =AVERAGE(B10:B10) -> 0 | D10: =ROUND(C10,0) -> 0 | E10: 2 | F10: 2
A11: =Stammdaten!A12&", "&Stammdaten!B12 -> Seidenberg, Miro | B11: =LN_GLN1!C14 -> 0 | C11: =AVERAGE(B11:B11) -> 0 | D11: =ROUND(C11,0) -> 0 | E11: 2 | F11: 3
A12: =Stammdaten!A13&", "&Stammdaten!B13 -> Kieselhain, Pia | B12: =LN_GLN1!C15 -> 0 | C12: =AVERAGE(B12:B12) -> 0 | D12: =ROUND(C12,0) -> 0 | E12: 2 | F12: 2
A13: =Stammdaten!A14&", "&Stammdaten!B14 -> Blaustein, Miro | B13: =LN_GLN1!C16 -> 0 | C13: =AVERAGE(B13:B13) -> 0 | D13: =ROUND(C13,0) -> 0 | E13: 2 | F13: 3
A14: =Stammdaten!A15&", "&Stammdaten!B15 -> Bergquell, Ari | B14: =LN_GLN1!C17 -> 0 | C14: =AVERAGE(B14:B14) -> 0 | D14: =ROUND(C14,0) -> 0 | E14: 2 | F14: 2
A15: =Stammdaten!A16&", "&Stammdaten!B16 -> Talwind, Jari | B15: =LN_GLN1!C18 -> 0 | C15: =AVERAGE(B15:B15) -> 0 | D15: =ROUND(C15,0) -> 0 | E15: 2 | F15: 2
A16: =Stammdaten!A17&", "&Stammdaten!B17 -> Farnheim, Bino | B16: =LN_GLN1!C19 -> 0 | C16: =AVERAGE(B16:B16) -> 0 | D16: =ROUND(C16,0) -> 0 | E16: 2 | F16: 2
A17: =Stammdaten!A19&", "&Stammdaten!B19 -> Tannenhof, Gina | B17: =LN_GLN1!C21 -> 0 | C17: =AVERAGE(B17:B17) -> 0 | D17: =ROUND(C17,0) -> 0 | E17: 2 | F17: 2
A18: =Stammdaten!A20&", "&Stammdaten!B20 -> Lindenfels, Miro | B18: =LN_GLN1!C22 -> 0 | C18: =AVERAGE(B18:B18) -> 0 | D18: =ROUND(C18,0) -> 0 | E18: 1 | F18: 2
A19: =Stammdaten!A21&", "&Stammdaten!B21 -> Adlerquell, Bino | B19: =LN_GLN1!C23 -> 0 | C19: =AVERAGE(B19:B19) -> 0 | D19: =ROUND(C19,0) -> 0 | E19: 1 | F19: 2
A20: =Stammdaten!A22&", "&Stammdaten!B22 -> Bergquell, Caro | B20: =LN_GLN1!C24 -> 0 | C20: =AVERAGE(B20:B20) -> 0 | D20: =ROUND(C20,0) -> 0 | E20: 1 | F20: 2
A21: =Stammdaten!A23&", "&Stammdaten!B23 -> Waldhauch, Gina | B21: =LN_GLN1!C25 -> 0 | C21: =AVERAGE(B21:B21) -> 0 | D21: =ROUND(C21,0) -> 0 | E21: 2 | F21: 2
A22: =Stammdaten!A24&", "&Stammdaten!B24 -> Silbersee, Miro | B22: =LN_GLN1!C26 -> 0 | C22: =AVERAGE(B22:B22) -> 0 | D22: =ROUND(C22,0) -> 0 | E22: 1
A23: =Stammdaten!A25&", "&Stammdaten!B25 -> Winterborn, Raya | B23: =LN_GLN1!C27 -> 0 | C23: =AVERAGE(B23:B23) -> 0 | D23: =ROUND(C23,0) -> 0 | E23: 2 | F23: 2
A24: =Stammdaten!A26&", "&Stammdaten!B26 -> Rosenquarz, Ivo | B24: =LN_GLN1!C28 -> 0 | C24: =AVERAGE(B24:B24) -> 0 | D24: =ROUND(C24,0) -> 0 | E24: 1 | F24: 3
A25: =Stammdaten!A27&", "&Stammdaten!B27 -> Mondenfels, Alma | B25: =LN_GLN1!C29 -> 0 | C25: =AVERAGE(B25:B25) -> 0 | D25: =ROUND(C25,0) -> 0 | E25: 1 | F25: 2
A26: =Stammdaten!A28&", "&Stammdaten!B28 -> Wolkenberg, Navi | B26: =LN_GLN1!C30 -> 0 | C26: =AVERAGE(B26:B26) -> 0 | D26: =ROUND(C26,0) -> 0 | E26: 1 | F26: 1
A27: =Stammdaten!A29&", "&Stammdaten!B29 -> Nordlicht, Navi | B27: =LN_GLN1!C31 -> 0 | C27: =AVERAGE(B27:B27) -> 0 | D27: =ROUND(C27,0) -> 0 | E27: 2 | F27: 1
A28: =Stammdaten!A30&", "&Stammdaten!B30 -> Lindenfels, Hedi | B28: =LN_GLN1!C32 -> 0 | C28: =AVERAGE(B28:B28) -> 0 | D28: =ROUND(C28,0) -> 0 | E28: 2 | F28: 3

Sheet Noten_HJ2
A1: Schüler | B1: SÜ Krypto | C1: Ø (gewichtet) | D1: Zeugnisnote | E1: Verhalten | F1: Mitarbeit
A2: =Stammdaten!A3&", "&Stammdaten!B3 -> Farnheim, Goro | B2: ='LN_SÜ Krypto'!M5 -> 4 | C2: =AVERAGE(B2:B2) -> 4 | D2: =ROUND(C2,0) -> 4 | E2: 1 | F2: 2
A3: =Stammdaten!A4&", "&Stammdaten!B4 -> Silbersee, Caro | B3: ='LN_SÜ Krypto'!M6 -> 9 | C3: =AVERAGE(B3:B3) -> 9 | D3: =ROUND(C3,0) -> 9 | F3: 2
A4: =Stammdaten!A5&", "&Stammdaten!B5 -> Adlerquell, Weya | B4: ='LN_SÜ Krypto'!M7 -> 8 | C4: =AVERAGE(B4:B4) -> 8 | D4: =ROUND(C4,0) -> 8 | E4: 2 | F4: 3
A5: =Stammdaten!A6&", "&Stammdaten!B6 -> Talwind, Demi | B5: ='LN_SÜ Krypto'!M8 -> 12 | C5: =AVERAGE(B5:B5) -> 12 | D5: =ROUND(C5,0) -> 12 | E5: 2 | F5: 1
A6: =Stammdaten!A7&", "&Stammdaten!B7 -> Nachtigall, Alma | B6: ='LN_SÜ Krypto'!M9 -> 11 | C6: =AVERAGE(B6:B6) -> 11 | D6: =ROUND(C6,0) -> 11 | E6: 1 | F6: 1
A7: =Stammdaten!A8&", "&Stammdaten!B8 -> Kieselhain, Tino | B7: ='LN_SÜ Krypto'!M10 -> 13 | C7: =AVERAGE(B7:B7) -> 13 | D7: =ROUND(C7,0) -> 13 | E7: 1 | F7: 2
A8: =Stammdaten!A9&", "&Stammdaten!B9 -> Talwind, Goro | B8: ='LN_SÜ Krypto'!M11 -> 5 | C8: =AVERAGE(B8:B8) -> 5 | D8: =ROUND(C8,0) -> 5 | E8: 1 | F8: 1
A9: =Stammdaten!A10&", "&Stammdaten!B10 -> Kornfeld, Nerio | B9: ='LN_SÜ Krypto'!M12 -> 11 | C9: =AVERAGE(B9:B9) -> 11 | D9: =ROUND(C9,0) -> 11 | E9: 2 | F9: 2
A10: =Stammdaten!A11&", "&Stammdaten!B11 -> Rosenquarz, Vito | B10: ='LN_SÜ Krypto'!M13 -> 6 | C10: =AVERAGE(B10:B10) -> 6 | D10: =ROUND(C10,0) -> 6 | E10: 2 | F10: 2
A11: =Stammdaten!A12&", "&Stammdaten!B12 -> Seidenberg, Miro | B11: ='LN_SÜ Krypto'!M14 -> 2 | C11: =AVERAGE(B11:B11) -> 2 | D11: =ROUND(C11,0) -> 2 | E11: 2 | F11: 2
A12: =Stammdaten!A13&", "&Stammdaten!B13 -> Kieselhain, Pia | B12: ='LN_SÜ Krypto'!M15 -> 9 | C12: =AVERAGE(B12:B12) -> 9 | D12: =ROUND(C12,0) -> 9 | E12: 2 | F12: 2
A13: =Stammdaten!A14&", "&Stammdaten!B14 -> Blaustein, Miro | B13: ='LN_SÜ Krypto'!M16 -> 12 | C13: =AVERAGE(B13:B13) -> 12 | D13: =ROUND(C13,0) -> 12 | E13: 2 | F13: 3
A14: =Stammdaten!A15&", "&Stammdaten!B15 -> Bergquell, Ari | B14: ='LN_SÜ Krypto'!M17 -> 5 | C14: =AVERAGE(B14:B14) -> 5 | D14: =ROUND(C14,0) -> 5 | E14: 2 | F14: 2
A15: =Stammdaten!A16&", "&Stammdaten!B16 -> Talwind, Jari | B15: ='LN_SÜ Krypto'!M18 -> 13 | C15: =AVERAGE(B15:B15) -> 13 | D15: =ROUND(C15,0) -> 13 | E15: 2 | F15: 2
A16: =Stammdaten!A17&", "&Stammdaten!B17 -> Farnheim, Bino | B16: ='LN_SÜ Krypto'!M19 -> 6 | C16: =AVERAGE(B16:B16) -> 6 | D16: =ROUND(C16,0) -> 6 | E16: 2 | F16: 2
A17: =Stammdaten!A19&", "&Stammdaten!B19 -> Tannenhof, Gina | B17: ='LN_SÜ Krypto'!M20 -> 8 | C17: =AVERAGE(B17:B17) -> 8 | D17: =ROUND(C17,0) -> 8 | E17: 2 | F17: 2
A18: =Stammdaten!A20&", "&Stammdaten!B20 -> Lindenfels, Miro | B18: ='LN_SÜ Krypto'!M21 -> 6 | C18: =AVERAGE(B18:B18) -> 6 | D18: =ROUND(C18,0) -> 6 | E18: 1 | F18: 1
A19: =Stammdaten!A21&", "&Stammdaten!B21 -> Adlerquell, Bino | B19: ='LN_SÜ Krypto'!M22 -> 12 | C19: =AVERAGE(B19:B19) -> 12 | D19: =ROUND(C19,0) -> 12 | E19: 1 | F19: 3
A20: =Stammdaten!A22&", "&Stammdaten!B22 -> Bergquell, Caro | B20: ='LN_SÜ Krypto'!M23 -> 4 | C20: =AVERAGE(B20:B20) -> 4 | D20: =ROUND(C20,0) -> 4 | E20: 1 | F20: 2
A21: =Stammdaten!A23&", "&Stammdaten!B23 -> Waldhauch, Gina | B21: ='LN_SÜ Krypto'!M24 -> 14 | C21: =AVERAGE(B21:B21) -> 14 | D21: =ROUND(C21,0) -> 14 | E21: 2 | F21: 1
A22: =Stammdaten!A24&", "&Stammdaten!B24 -> Silbersee, Miro | B22: ='LN_SÜ Krypto'!M25 -> 15 | C22: =AVERAGE(B22:B22) -> 15 | D22: =ROUND(C22,0) -> 15 | E22: 1
A23: =Stammdaten!A25&", "&Stammdaten!B25 -> Winterborn, Raya | B23: ='LN_SÜ Krypto'!M26 -> 14 | C23: =AVERAGE(B23:B23) -> 14 | D23: =ROUND(C23,0) -> 14 | E23: 2 | F23: 3
A24: =Stammdaten!A26&", "&Stammdaten!B26 -> Rosenquarz, Ivo | B24: ='LN_SÜ Krypto'!M27 -> 6 | C24: =AVERAGE(B24:B24) -> 6 | D24: =ROUND(C24,0) -> 6 | E24: 1 | F24: 2
A25: =Stammdaten!A27&", "&Stammdaten!B27 -> Mondenfels, Alma | B25: ='LN_SÜ Krypto'!M28 -> 13 | C25: =AVERAGE(B25:B25) -> 13 | D25: =ROUND(C25,0) -> 13 | E25: 1 | F25: 1
A26: =Stammdaten!A28&", "&Stammdaten!B28 -> Wolkenberg, Navi | B26: ='LN_SÜ Krypto'!M29 -> 12 | C26: =AVERAGE(B26:B26) -> 12 | D26: =ROUND(C26,0) -> 12 | E26: 1 | F26: 1
A27: =Stammdaten!A29&", "&Stammdaten!B29 -> Nordlicht, Navi | B27: ='LN_SÜ Krypto'!M30 -> 8 | C27: =AVERAGE(B27:B27) -> 8 | D27: =ROUND(C27,0) -> 8 | E27: 2 | F27: 1
A28: =Stammdaten!A30&", "&Stammdaten!B30 -> Lindenfels, Hedi | B28: ='LN_SÜ Krypto'!M31 -> 14 | C28: =AVERAGE(B28:B28) -> 14 | D28: =ROUND(C28,0) -> 14 | E28: 2 | F28: 3

Sheet Noten_Jahr
A1: Schüler | B1: GLN1 | C1: SÜ Krypto | D1: Ø (gewichtet) | E1: Zeugnisnote | F1: Verhalten | G1: Mitarbeit
A2: =Stammdaten!A3&", "&Stammdaten!B3 -> Farnheim, Goro | B2: =LN_GLN1!C5 -> 0 | C2: ='LN_SÜ Krypto'!M5 -> 4 | D2: =AVERAGE(B2:C2) -> 2 | E2: =ROUND(D2,0) -> 2 | F2: 1 | G2: 2
A3: =Stammdaten!A4&", "&Stammdaten!B4 -> Silbersee, Caro | B3: =LN_GLN1!C6 -> 0 | C3: ='LN_SÜ Krypto'!M6 -> 9 | D3: =AVERAGE(B3:C3) -> 4.5 | E3: =ROUND(D3,0) -> 5 | G3: 2
A4: =Stammdaten!A5&", "&Stammdaten!B5 -> Adlerquell, Weya | B4: =LN_GLN1!C7 -> 0 | C4: ='LN_SÜ Krypto'!M7 -> 8 | D4: =AVERAGE(B4:C4) -> 4 | E4: =ROUND(D4,0) -> 4 | F4: 2 | G4: 3
A5: =Stammdaten!A6&", "&Stammdaten!B6 -> Talwind, Demi | B5: =LN_GLN1!C8 -> 0 | C5: ='LN_SÜ Krypto'!M8 -> 12 | D5: =AVERAGE(B5:C5) -> 6 | E5: =ROUND(D5,0) -> 6 | F5: 2 | G5: 1
A6: =Stammdaten!A7&", "&Stammdaten!B7 -> Nachtigall, Alma | B6: =LN_GLN1!C9 -> 0 | C6: ='LN_SÜ Krypto'!M9 -> 11 | D6: =AVERAGE(B6:C6) -> 5.5 | E6: =ROUND(D6,0) -> 6 | F6: 1 | G6: 1
A7: =Stammdaten!A8&", "&Stammdaten!B8 -> Kieselhain, Tino | B7: =LN_GLN1!C10 -> 0 | C7: ='LN_SÜ Krypto'!M10 -> 13 | D7: =AVERAGE(B7:C7) -> 6.5 | E7: =ROUND(D7,0) -> 7 | F7: 1 | G7: 2
A8: =Stammdaten!A9&", "&Stammdaten!B9 -> Talwind, Goro | B8: =LN_GLN1!C11 -> 0 | C8: ='LN_SÜ Krypto'!M11 -> 5 | D8: =AVERAGE(B8:C8) -> 2.5 | E8: =ROUND(D8,0) -> 3 | F8: 1 | G8: 1
A9: =Stammdaten!A10&", "&Stammdaten!B10 -> Kornfeld, Nerio | B9: =LN_GLN1!C12 -> 0 | C9: ='LN_SÜ Krypto'!M12 -> 11 | D9: =AVERAGE(B9:C9) -> 5.5 | E9: =ROUND(D9,0) -> 6 | F9: 2 | G9: 2
A10: =Stammdaten!A11&", "&Stammdaten!B11 -> Rosenquarz, Vito | B10: =LN_GLN1!C13 -> 0 | C10: ='LN_SÜ Krypto'!M13 -> 6 | D10: =AVERAGE(B10:C10) -> 3 | E10: =ROUND(D10,0) -> 3 | F10: 2 | G10: 2
A11: =Stammdaten!A12&", "&Stammdaten!B12 -> Seidenberg, Miro | B11: =LN_GLN1!C14 -> 0 | C11: ='LN_SÜ Krypto'!M14 -> 2 | D11: =AVERAGE(B11:C11) -> 1 | E11: =ROUND(D11,0) -> 1 | F11: 2 | G11: 2
A12: =Stammdaten!A13&", "&Stammdaten!B13 -> Kieselhain, Pia | B12: =LN_GLN1!C15 -> 0 | C12: ='LN_SÜ Krypto'!M15 -> 9 | D12: =AVERAGE(B12:C12) -> 4.5 | E12: =ROUND(D12,0) -> 5 | F12: 2 | G12: 2
A13: =Stammdaten!A14&", "&Stammdaten!B14 -> Blaustein, Miro | B13: =LN_GLN1!C16 -> 0 | C13: ='LN_SÜ Krypto'!M16 -> 12 | D13: =AVERAGE(B13:C13) -> 6 | E13: =ROUND(D13,0) -> 6 | F13: 2 | G13: 3
A14: =Stammdaten!A15&", "&Stammdaten!B15 -> Bergquell, Ari | B14: =LN_GLN1!C17 -> 0 | C14: ='LN_SÜ Krypto'!M17 -> 5 | D14: =AVERAGE(B14:C14) -> 2.5 | E14: =ROUND(D14,0) -> 3 | F14: 2 | G14: 2
A15: =Stammdaten!A16&", "&Stammdaten!B16 -> Talwind, Jari | B15: =LN_GLN1!C18 -> 0 | C15: ='LN_SÜ Krypto'!M18 -> 13 | D15: =AVERAGE(B15:C15) -> 6.5 | E15: =ROUND(D15,0) -> 7 | F15: 2 | G15: 2
A16: =Stammdaten!A17&", "&Stammdaten!B17 -> Farnheim, Bino | B16: =LN_GLN1!C19 -> 0 | C16: ='LN_SÜ Krypto'!M19 -> 6 | D16: =AVERAGE(B16:C16) -> 3 | E16: =ROUND(D16,0) -> 3 | F16: 2 | G16: 2
